Workbook
Name Fim: #REF!
Name Fim: #REF!
Name Fim: #REF!
Name Fim: #REF!
Name Fim: #REF!
Name Fim: #REF!
Name Fim: #REF!

Sheet LISTA CORRIDA
A1: SÉRIE | B1: Nº | C1: RM | D1: NOME DO ALUNO | E1: S | F1: COD | G1: NASC. | H1: RA | I1: RG | J1: CPF | K1: OBS. | L1: ED. FÍSICA | M1: REM - 2020/2º | N1: IDADE | O1: NATURALIDADE | P1: HORÁRIO | Q1: HORÁRIO ED FÍSICA | R1: INCLUSÃO | S1: PROFESSOR | T1: PLANO DE AÇÃO | U1: AEE | V1: DEFICIENCIA | W1: OBS DEFICIENCIA: | X1: C. RODAS | Y1: ADEQUAÇÕES | Z1: TIPO TE | AA1: LOCAL TE | AB1: NÍVEL ANO | AC1: ATENDIMENTOS DE SAÚDE | AD1: SEMESTRE
A2: =RIGHT('[1]1ª'!$A$5:$D$5,12) -> 1ª SÉRIE E.F | B2: 1 | C2: ='1ª'!#REF! -> #REF! | D2: ='1ª'!#REF! -> #REF! | E2: ='1ª'!#REF! -> #REF! | F2: ='1ª'!#REF! -> #REF! | G2: ='1ª'!#REF! -> #REF! | H2: ='1ª'!#REF! -> #REF! | I2: ='1ª'!#REF! -> #REF! | K2: ='1ª'!#REF! -> #REF! | L2: ='1ª'!#REF! -> #REF! | N2: ='1ª'!#REF! -> #REF! | P2: 19:00 às 23:00 | Q2: Terça e Quinta-feira 19h00 - 20h00 | R2: ='1ª'!#REF! -> #REF! | S2: ='1ª'!#REF! -> #REF! | T2: ='1ª'!#REF! -> #REF! | U2: ='1ª'!#REF! -> #REF! | V2: ='1ª'!#REF! -> #REF! | W2: ='1ª'!#REF! -> #REF! | X2: ='1ª'!#REF! -> #REF! | Y2: ='1ª'!#REF! -> #REF! | ... AA2: ='1ª'!#REF! -> #REF! | AB2: 1ª série EJA | AD2: 2º SEMESTRE
A3: =RIGHT('[1]1ª'!$A$5:$D$5,12) -> 1ª SÉRIE E.F | B3: 2 | C3: ='1ª'!#REF! -> #REF! | D3: ='1ª'!#REF! -> #REF! | E3: ='1ª'!#REF! -> #REF! | F3: ='1ª'!#REF! -> #REF! | G3: ='1ª'!#REF! -> #REF! | H3: ='1ª'!#REF! -> #REF! | I3: ='1ª'!#REF! -> #REF! | K3: ='1ª'!#REF! -> #REF! | L3: ='1ª'!#REF! -> #REF! | N3: ='1ª'!#REF! -> #REF! | P3: 19:00 às 23:00 | Q3: Terça e Quinta-feira 19h00 - 20h00 | R3: ='1ª'!#REF! -> #REF! | S3: ='1ª'!#REF! -> #REF! | T3: ='1ª'!#REF! -> #REF! | U3: ='1ª'!#REF! -> #REF! | V3: ='1ª'!#REF! -> #REF! | W3: ='1ª'!#REF! -> #REF! | X3: ='1ª'!#REF! -> #REF! | Y3: ='1ª'!#REF! -> #REF! | ... AA3: ='1ª'!#REF! -> #REF! | AB3: 1ª série EJA | AD3: 2º SEMESTRE
A4: =RIGHT('[1]1ª'!$A$5:$D$5,12) -> 1ª SÉRIE E.F | B4: 3 | C4: ='1ª'!$B7 -> 16345 | D4: ='1ª'!$C7 -> ELAINE FRANCISCO DE QUEIROZ | E4: ='1ª'!$D7 -> F | F4: ='1ª'!$E7 -> MA | G4: ='1ª'!$F7 -> 30376 | H4: ='1ª'!$G7 -> 0 | I4: ='1ª'!$H7 -> 0 | K4: ='1ª'!$I7 -> 0 | L4: ='1ª'!$J7 -> DISP.IDADE | N4: ='1ª'!$K7 -> 42 | P4: 19:00 às 23:00 | Q4: Terça e Quinta-feira 19h00 - 20h00 | R4: ='1ª'!L7 -> Não | S4: ='1ª'!M7 -> Eliane | T4: ='1ª'!N7 -> - | U4: ='1ª'!O7 -> - | V4: ='1ª'!P7 -> - | W4: ='1ª'!Q7 -> - | X4: ='1ª'!R7 -> - | Y4: ='1ª'!S7 -> - | ... AA4: ='1ª'!U7 -> 0 | AB4: 1ª série EJA | AD4: 2º SEMESTRE
A5: =RIGHT('[1]1ª'!$A$5:$D$5,12) -> 1ª SÉRIE E.F | B5: 4 | C5: ='1ª'!$B8 -> 18904 | D5: ='1ª'!$C8 -> LENI RODRIGUES DIAS | E5: ='1ª'!$D8 -> F | F5: ='1ª'!$E8 -> MA | G5: ='1ª'!$F8 -> 23323 | H5: ='1ª'!$G8 -> 0 | I5: ='1ª'!$H8 -> 0 | K5: ='1ª'!$I8 -> 0 | L5: ='1ª'!$J8 -> DISP.IDADE | N5: ='1ª'!$K8 -> 61 | P5: 19:00 às 23:00 | Q5: Terça e Quinta-feira 19h00 - 20h00 | R5: ='1ª'!L8 -> Não | S5: ='1ª'!M8 -> Eliane | T5: ='1ª'!N8 -> - | U5: ='1ª'!O8 -> - | V5: ='1ª'!P8 -> - | W5: ='1ª'!Q8 -> - | X5: ='1ª'!R8 -> - | Y5: ='1ª'!S8 -> - | ... AA5: ='1ª'!U8 -> 0 | AB5: 1ª série EJA | AD5: 2º SEMESTRE
A6: =RIGHT('[1]1ª'!$A$5:$D$5,12) -> 1ª SÉRIE E.F | B6: 5 | C6: ='1ª'!$B9 -> 18828 | D6: ='1ª'!$C9 -> MARIA DA SOLEDADE PENHA SILVA | E6: ='1ª'!$D9 -> F | F6: ='1ª'!$E9 -> MA | G6: ='1ª'!$F9 -> 25983 | H6: ='1ª'!$G9 -> 1258776170 | I6: ='1ª'!$H9 -> 36934088-7 | K6: ='1ª'!$I9 -> 0 | L6: ='1ª'!$J9 -> DISP.IDADE | N6: ='1ª'!$K9 -> 54 | P6: 19:00 às 23:00 | Q6: Terça e Quinta-feira 19h00 - 20h00 | R6: ='1ª'!L9 -> Não | S6: ='1ª'!M9 -> Eliane | T6: ='1ª'!N9 -> - | U6: ='1ª'!O9 -> - | V6: ='1ª'!P9 -> - | W6: ='1ª'!Q9 -> - | X6: ='1ª'!R9 -> - | Y6: ='1ª'!S9 -> - | ... AA6: ='1ª'!U9 -> 0 | AB6: 1ª série EJA | AD6: 2º SEMESTRE
A7: =RIGHT('[1]1ª'!$A$5:$D$5,12) -> 1ª SÉRIE E.F | B7: 6 | C7: ='1ª'!$B10 -> 0 | D7: ='1ª'!$C10 -> 0 | E7: ='1ª'!$D10 -> 0 | F7: ='1ª'!$E10 | G7: ='1ª'!$F10 -> 0 | H7: ='1ª'!$G10 -> 0 | I7: ='1ª'!$H10 -> 0 | K7: ='1ª'!$I10 -> 0 | L7: ='1ª'!$J10 | N7: ='1ª'!$K10 | P7: 19:00 às 23:00 | Q7: Terça e Quinta-feira 19h00 - 20h00 | R7: ='1ª'!L10 -> Não | S7: ='1ª'!M10 -> Eliane | T7: ='1ª'!N10 -> - | U7: ='1ª'!O10 -> - | V7: ='1ª'!P10 -> - | W7: ='1ª'!Q10 -> - | X7: ='1ª'!R10 -> - | Y7: ='1ª'!S10 -> - | ... AA7: ='1ª'!U10 -> 0 | AB7: 1ª série EJA | AD7: 2º SEMESTRE
A8: =RIGHT('[1]1ª'!$A$5:$D$5,12) -> 1ª SÉRIE E.F | B8: 7 | C8: ='1ª'!$B11 -> 0 | D8: ='1ª'!$C11 -> 0 | E8: ='1ª'!$D11 -> 0 | F8: ='1ª'!$E11 | G8: ='1ª'!$F11 -> 0 | H8: ='1ª'!$G11 -> 0 | I8: ='1ª'!$H11 -> 0 | K8: ='1ª'!$I11 -> 0 | L8: ='1ª'!$J11 | N8: ='1ª'!$K11 | P8: 19:00 às 23:00 | Q8: Terça e Quinta-feira 19h00 - 20h00 | R8: ='1ª'!L11 -> Não | S8: ='1ª'!M11 -> Eliane | T8: ='1ª'!N11 -> - | U8: ='1ª'!O11 -> - | V8: ='1ª'!P11 -> - | W8: ='1ª'!Q11 -> - | X8: ='1ª'!R11 -> - | Y8: ='1ª'!S11 -> - | ... AA8: ='1ª'!U11 -> 0 | AB8: 1ª série EJA | AD8: 2º SEMESTRE
A9: =RIGHT('[1]1ª'!$A$5:$D$5,12) -> 1ª SÉRIE E.F | B9: 8 | C9: ='1ª'!$B12 -> 0 | D9: ='1ª'!$C12 -> 0 | E9: ='1ª'!$D12 -> 0 | F9: ='1ª'!$E12 | G9: ='1ª'!$F12 -> 0 | H9: ='1ª'!$G12 -> 0 | I9: ='1ª'!$H12 -> 0 | K9: ='1ª'!$I12 -> 0 | L9: ='1ª'!$J12 | N9: ='1ª'!$K12 | P9: 19:00 às 23:00 | Q9: Terça e Quinta-feira 19h00 - 20h00 | R9: ='1ª'!L12 -> Não | S9: ='1ª'!M12 -> Eliane | T9: ='1ª'!N12 -> - | U9: ='1ª'!O12 -> - | V9: ='1ª'!P12 -> - | W9: ='1ª'!Q12 -> - | X9: ='1ª'!R12 -> - | Y9: ='1ª'!S12 -> - | ... AA9: ='1ª'!U12 -> 0 | AB9: 1ª série EJA | AD9: 2º SEMESTRE
A10: =RIGHT('[1]1ª'!$A$5:$D$5,12) -> 1ª SÉRIE E.F | B10: 9 | C10: ='1ª'!$B13 -> 0 | D10: ='1ª'!$C13 -> 0 | E10: ='1ª'!$D13 -> 0 | F10: ='1ª'!$E13 | G10: ='1ª'!$F13 -> 0 | H10: ='1ª'!$G13 -> 0 | I10: ='1ª'!$H13 -> 0 | K10: ='1ª'!$I13 -> 0 | L10: ='1ª'!$J13 | N10: ='1ª'!$K13 | P10: 19:00 às 23:00 | Q10: Terça e Quinta-feira 19h00 - 20h00 | R10: ='1ª'!L13 -> Não | S10: ='1ª'!M13 -> Eliane | T10: ='1ª'!N13 -> - | U10: ='1ª'!O13 -> - | V10: ='1ª'!P13 -> - | W10: ='1ª'!Q13 -> - | X10: ='1ª'!R13 -> - | Y10: ='1ª'!S13 -> - | ... AA10: ='1ª'!U13 -> 0 | AB10: 1ª série EJA | AD10: 2º SEMESTRE
A11: =RIGHT('[1]1ª'!$A$5:$D$5,12) -> 1ª SÉRIE E.F | B11: 10 | C11: ='1ª'!$B14 -> 0 | D11: ='1ª'!$C14 -> 0 | E11: ='1ª'!$D14 -> 0 | F11: ='1ª'!$E14 | G11: ='1ª'!$F14 -> 0 | H11: ='1ª'!$G14 -> 0 | I11: ='1ª'!$H14 -> 0 | K11: ='1ª'!$I14 -> 0 | L11: ='1ª'!$J14 | N11: ='1ª'!$K14 | P11: 19:00 às 23:00 | Q11: Terça e Quinta-feira 19h00 - 20h00 | R11: ='1ª'!L14 -> Não | S11: ='1ª'!M14 -> Eliane | T11: ='1ª'!N14 -> - | U11: ='1ª'!O14 -> - | V11: ='1ª'!P14 -> - | W11: ='1ª'!Q14 -> - | X11: ='1ª'!R14 -> - | Y11: ='1ª'!S14 -> - | ... AA11: ='1ª'!U14 -> 0 | AB11: 1ª série EJA | AD11: 2º SEMESTRE
A12: =RIGHT('[1]1ª'!$A$5:$D$5,12) -> 1ª SÉRIE E.F | B12: 11 | C12: ='1ª'!$B15 -> 0 | D12: ='1ª'!$C15 -> 0 | E12: ='1ª'!$D15 -> 0 | F12: ='1ª'!$E15 | G12: ='1ª'!$F15 -> 0 | H12: ='1ª'!$G15 -> 0 | I12: ='1ª'!$H15 -> 0 | K12: ='1ª'!$I15 -> 0 | L12: ='1ª'!$J15 | N12: ='1ª'!$K15 | P12: 19:00 às 23:00 | Q12: Terça e Quinta-feira 19h00 - 20h00 | R12: ='1ª'!L15 -> Não | S12: ='1ª'!M15 -> Eliane | T12: ='1ª'!N15 -> - | U12: ='1ª'!O15 -> - | V12: ='1ª'!P15 -> - | W12: ='1ª'!Q15 -> - | X12: ='1ª'!R15 -> - | Y12: ='1ª'!S15 -> - | ... AA12: ='1ª'!U15 -> 0 | AB12: 1ª série EJA | AD12: 2º SEMESTRE
A13: =RIGHT('[1]1ª'!$A$5:$D$5,12) -> 1ª SÉRIE E.F | B13: 12 | C13: ='1ª'!$B16 -> 0 | D13: ='1ª'!$C16 -> 0 | E13: ='1ª'!$D16 -> 0 | F13: ='1ª'!$E16 | G13: ='1ª'!$F16 -> 0 | H13: ='1ª'!$G16 -> 0 | I13: ='1ª'!$H16 -> 0 | K13: ='1ª'!$I16 -> 0 | L13: ='1ª'!$J16 | N13: ='1ª'!$K16 | P13: 19:00 às 23:00 | Q13: Terça e Quinta-feira 19h00 - 20h00 | R13: ='1ª'!L16 -> Não | S13: ='1ª'!M16 -> Eliane | T13: ='1ª'!N16 -> - | U13: ='1ª'!O16 -> - | V13: ='1ª'!P16 -> - | W13: ='1ª'!Q16 -> - | X13: ='1ª'!R16 -> - | Y13: ='1ª'!S16 -> - | ... AA13: ='1ª'!U16 -> 0 | AB13: 1ª série EJA | AD13: 2º SEMESTRE
A14: =RIGHT('[1]1ª'!$A$5:$D$5,12) -> 1ª SÉRIE E.F | B14: 13 | C14: ='1ª'!$B17 -> 0 | D14: ='1ª'!$C17 -> 0 | E14: ='1ª'!$D17 -> 0 | F14: ='1ª'!$E17 | G14: ='1ª'!$F17 -> 0 | H14: ='1ª'!$G17 -> 0 | I14: ='1ª'!$H17 -> 0 | K14: ='1ª'!$I17 -> 0 | L14: ='1ª'!$J17 | N14: ='1ª'!$K17 | P14: 19:00 às 23:00 | Q14: Terça e Quinta-feira 19h00 - 20h00 | R14: ='1ª'!L17 -> Não | S14: ='1ª'!M17 -> Eliane | T14: ='1ª'!N17 -> - | U14: ='1ª'!O17 -> - | V14: ='1ª'!P17 -> - | W14: ='1ª'!Q17 -> - | X14: ='1ª'!R17 -> - | Y14: ='1ª'!S17 -> - | ... AA14: ='1ª'!U17 -> 0 | AB14: 1ª série EJA | AD14: 2º SEMESTRE
A15: =RIGHT('[1]1ª'!$A$5:$D$5,12) -> 1ª SÉRIE E.F | B15: 14 | C15: ='1ª'!$B18 -> 0 | D15: ='1ª'!$C18 -> 0 | E15: ='1ª'!$D18 -> 0 | F15: ='1ª'!$E18 | G15: ='1ª'!$F18 -> 0 | H15: ='1ª'!$G18 -> 0 | I15: ='1ª'!$H18 -> 0 | K15: ='1ª'!$I18 -> 0 | L15: ='1ª'!$J18 | N15: ='1ª'!$K18 | P15: 19:00 às 23:00 | Q15: Terça e Quinta-feira 19h00 - 20h00 | R15: ='1ª'!L18 -> Não | S15: ='1ª'!M18 -> Eliane | T15: ='1ª'!N18 -> - | U15: ='1ª'!O18 -> - | V15: ='1ª'!P18 -> - | W15: ='1ª'!Q18 -> - | X15: ='1ª'!R18 -> - | Y15: ='1ª'!S18 -> - | ... AA15: ='1ª'!U18 -> 0 | AB15: 1ª série EJA | AD15: 2º SEMESTRE
... A56: =RIGHT('[1]1ª'!$A$5:$D$5,12) -> 1ª SÉRIE E.F | B56: 55 | C56: ='1ª'!$B59 -> 0 | D56: ='1ª'!$C59 -> 0 | E56: ='1ª'!$D59 -> 0 | F56: ='1ª'!$E59 -> 0 | G56: ='1ª'!$F59 -> 0 | H56: ='1ª'!$G59 -> 0 | I56: ='1ª'!$H59 -> 0 | K56: ='1ª'!$I59 -> 0 | L56: ='1ª'!$J59 -> 0 | N56: ='1ª'!$K59 -> 0 | P56: 19:00 às 23:00 | Q56: Terça e Quinta-feira 19h00 - 20h00 | R56: ='1ª'!L59 -> 0 | S56: ='1ª'!M59 -> 0 | T56: ='1ª'!N59 -> 0 | U56: ='1ª'!O59 -> 0 | V56: ='1ª'!P59 -> 0 | W56: ='1ª'!Q59 -> 0 | X56: ='1ª'!R59 -> 0 | Y56: ='1ª'!S59 -> 0 | ... AA56: ='1ª'!U59 -> 0 | AB56: 1ª série EJA | AD56: 2º SEMESTRE
A57: =RIGHT('[1]2ª'!$A$5:$D$5,12) -> 2ª SÉRIE E.F | B57: 1 | C57: ='2ª'!$B7 -> 13512 | D57: ='2ª'!$C7 -> ADMILSON FRANCISCO DE SANTANA | E57: ='2ª'!$D7 -> M | F57: ='2ª'!$E7 -> MA | G57: ='2ª'!$F7 -> 31434 | H57: ='2ª'!$G7 -> 113917115-X | I57: ='2ª'!$H7 -> 56170354-1 | K57: ='2ª'!$I7 -> 0 | L57: ='2ª'!$J7 -> DISP.IDADE | N57: ='2ª'!$K7 -> 39 | P57: 19:00 às 23:00 | Q57: Terça e Quinta-feira 19h00 - 20h00 | R57: ='2ª'!L7 -> Não | S57: ='2ª'!M7 -> Eliane | T57: ='2ª'!N7 -> - | U57: ='2ª'!O7 -> - | V57: ='2ª'!P7 -> - | W57: ='2ª'!Q7 -> - | X57: ='2ª'!R7 -> - | Y57: ='2ª'!S7 -> - | ... AA57: ='2ª'!U7 -> 0 | AB57: 2ª série EJA | AD57: 2º SEMESTRE
A58: =RIGHT('[1]2ª'!$A$5:$D$5,12) -> 2ª SÉRIE E.F | B58: 2 | C58: ='2ª'!#REF! -> #REF! | D58: ='2ª'!#REF! -> #REF! | E58: ='2ª'!#REF! -> #REF! | F58: ='2ª'!#REF! -> #REF! | G58: ='2ª'!#REF! -> #REF! | H58: ='2ª'!#REF! -> #REF! | I58: ='2ª'!#REF! -> #REF! | K58: ='2ª'!#REF! -> #REF! | L58: ='2ª'!#REF! -> #REF! | N58: ='2ª'!#REF! -> #REF! | P58: 19:00 às 23:00 | Q58: Terça e Quinta-feira 19h00 - 20h00 | R58: ='2ª'!#REF! -> #REF! | S58: ='2ª'!#REF! -> #REF! | T58: ='2ª'!#REF! -> #REF! | U58: ='2ª'!#REF! -> #REF! | V58: ='2ª'!#REF! -> #REF! | W58: ='2ª'!#REF! -> #REF! | X58: ='2ª'!#REF! -> #REF! | Y58: ='2ª'!#REF! -> #REF! | ... AA58: ='2ª'!#REF! -> #REF! | AB58: 2ª série EJA | AD58: 2º SEMESTRE
A59: =RIGHT('[1]2ª'!$A$5:$D$5,12) -> 2ª SÉRIE E.F | B59: 3 | C59: ='2ª'!$B8 -> 18908 | D59: ='2ª'!$C8 -> ELIANE IRENE DA SILVA SANTOS | E59: ='2ª'!$D8 -> F | F59: ='2ª'!$E8 -> MA | G59: ='2ª'!$F8 -> 26448 | H59: ='2ª'!$G8 -> 0 | I59: ='2ª'!$H8 -> 0 | K59: ='2ª'!$I8 -> 0 | L59: ='2ª'!$J8 -> DISP.IDADE | N59: ='2ª'!$K8 -> 53 | P59: 19:00 às 23:00 | Q59: Terça e Quinta-feira 19h00 - 20h00 | R59: ='2ª'!L8 -> Não | S59: ='2ª'!M8 -> Eliane | T59: ='2ª'!N8 -> - | U59: ='2ª'!O8 -> - | V59: ='2ª'!P8 -> - | W59: ='2ª'!Q8 -> - | X59: ='2ª'!R8 -> - | Y59: ='2ª'!S8 -> - | ... AA59: ='2ª'!U8 -> 0 | AB59: 2ª série EJA | AD59: 2º SEMESTRE
A60: =RIGHT('[1]2ª'!$A$5:$D$5,12) -> 2ª SÉRIE E.F | B60: 4 | C60: ='2ª'!$B9 -> 18911 | D60: ='2ª'!$C9 -> RITA DOS SANTOS CORREIA | E60: ='2ª'!$D9 -> F | F60: ='2ª'!$E9 -> MA | G60: ='2ª'!$F9 -> 16697 | H60: ='2ª'!$G9 -> 32468373-X | I60: ='2ª'!$H9 -> 0 | K60: ='2ª'!$I9 -> 0 | L60: ='2ª'!$J9 -> DISP.IDADE | N60: ='2ª'!$K9 -> 80 | P60: 19:00 às 23:00 | Q60: Terça e Quinta-feira 19h00 - 20h00 | R60: ='2ª'!L9 -> Não | S60: ='2ª'!M9 -> Eliane | T60: ='2ª'!N9 -> - | U60: ='2ª'!O9 -> - | V60: ='2ª'!P9 -> - | W60: ='2ª'!Q9 -> - | X60: ='2ª'!R9 -> - | Y60: ='2ª'!S9 -> - | ... AA60: ='2ª'!U9 -> 0 | AB60: 2ª série EJA | AD60: 2º SEMESTRE
A61: =RIGHT('[1]2ª'!$A$5:$D$5,12) -> 2ª SÉRIE E.F | B61: 5 | C61: ='2ª'!$B10 -> 18970 | D61: ='2ª'!$C10 -> MARIA CLEUSA DOS SANTOS | E61: ='2ª'!$D10 -> F | F61: ='2ª'!$E10 -> MA | G61: ='2ª'!$F10 -> 25393 | H61: ='2ª'!$G10 -> 0 | I61: ='2ª'!$H10 -> 25427262-9 | K61: ='2ª'!$I10 -> 0 | L61: ='2ª'!$J10 -> DISP.IDADE | N61: ='2ª'!$K10 -> 56 | P61: 19:00 às 23:00 | Q61: Terça e Quinta-feira 19h00 - 20h00 | R61: ='2ª'!L10 -> Não | S61: ='2ª'!M10 -> Eliane | T61: ='2ª'!N10 -> - | U61: ='2ª'!O10 -> - | V61: ='2ª'!P10 -> - | W61: ='2ª'!Q10 -> - | X61: ='2ª'!R10 -> - | Y61: ='2ª'!S10 -> - | ... AA61: ='2ª'!U10 -> 0 | AB61: 2ª série EJA | AD61: 2º SEMESTRE
A62: =RIGHT('[1]2ª'!$A$5:$D$5,12) -> 2ª SÉRIE E.F | B62: 6 | C62: ='2ª'!$B11 -> 0 | D62: ='2ª'!$C11 -> 0 | E62: ='2ª'!$D11 -> 0 | F62: ='2ª'!$E11 | G62: ='2ª'!$F11 -> 0 | H62: ='2ª'!$G11 -> 0 | I62: ='2ª'!$H11 -> 0 | K62: ='2ª'!$I11 -> 0 | L62: ='2ª'!$J11 | N62: ='2ª'!$K11 | P62: 19:00 às 23:00 | Q62: Terça e Quinta-feira 19h00 - 20h00 | R62: ='2ª'!L11 -> Não | S62: ='2ª'!M11 -> Eliane | T62: ='2ª'!N11 -> - | U62: ='2ª'!O11 -> - | V62: ='2ª'!P11 -> - | W62: ='2ª'!Q11 -> - | X62: ='2ª'!R11 -> - | Y62: ='2ª'!S11 -> - | ... AA62: ='2ª'!U11 -> 0 | AB62: 2ª série EJA | AD62: 2º SEMESTRE
A63: =RIGHT('[1]2ª'!$A$5:$D$5,12) -> 2ª SÉRIE E.F | B63: 7 | C63: ='2ª'!$B12 -> 0 | D63: ='2ª'!$C12 -> 0 | E63: ='2ª'!$D12 -> 0 | F63: ='2ª'!$E12 | G63: ='2ª'!$F12 -> 0 | H63: ='2ª'!$G12 -> 0 | I63: ='2ª'!$H12 -> 0 | K63: ='2ª'!$I12 -> 0 | L63: ='2ª'!$J12 | N63: ='2ª'!$K12 | P63: 19:00 às 23:00 | Q63: Terça e Quinta-feira 19h00 - 20h00 | R63: ='2ª'!L12 -> Não | S63: ='2ª'!M12 -> Eliane | T63: ='2ª'!N12 -> - | U63: ='2ª'!O12 -> - | V63: ='2ª'!P12 -> - | W63: ='2ª'!Q12 -> - | X63: ='2ª'!R12 -> - | Y63: ='2ª'!S12 -> - | ... AA63: ='2ª'!U12 -> 0 | AB63: 2ª série EJA | AD63: 2º SEMESTRE
A64: =RIGHT('[1]2ª'!$A$5:$D$5,12) -> 2ª SÉRIE E.F | B64: 8 | C64: ='2ª'!$B13 -> 0 | D64: ='2ª'!$C13 -> 0 | E64: ='2ª'!$D13 -> 0 | F64: ='2ª'!$E13 | G64: ='2ª'!$F13 -> 0 | H64: ='2ª'!$G13 -> 0 | I64: ='2ª'!$H13 -> 0 | K64: ='2ª'!$I13 -> 0 | L64: ='2ª'!$J13 | N64: ='2ª'!$K13 | P64: 19:00 às 23:00 | Q64: Terça e Quinta-feira 19h00 - 20h00 | R64: ='2ª'!L13 -> Não | S64: ='2ª'!M13 -> Eliane | T64: ='2ª'!N13 -> - | U64: ='2ª'!O13 -> - | V64: ='2ª'!P13 -> - | W64: ='2ª'!Q13 -> - | X64: ='2ª'!R13 -> - | Y64: ='2ª'!S13 -> - | ... AA64: ='2ª'!U13 -> 0 | AB64: 2ª série EJA | AD64: 2º SEMESTRE
A65: =RIGHT('[1]2ª'!$A$5:$D$5,12) -> 2ª SÉRIE E.F | B65: 9 | C65: ='2ª'!$B14 -> 0 | D65: ='2ª'!$C14 -> 0 | E65: ='2ª'!$D14 -> 0 | F65: ='2ª'!$E14 | G65: ='2ª'!$F14 -> 0 | H65: ='2ª'!$G14 -> 0 | I65: ='2ª'!$H14 -> 0 | K65: ='2ª'!$I14 -> 0 | L65: ='2ª'!$J14 | N65: ='2ª'!$K14 | P65: 19:00 às 23:00 | Q65: Terça e Quinta-feira 19h00 - 20h00 | R65: ='2ª'!L14 -> Não | S65: ='2ª'!M14 -> Eliane | T65: ='2ª'!N14 -> - | U65: ='2ª'!O14 -> - | V65: ='2ª'!P14 -> - | W65: ='2ª'!Q14 -> - | X65: ='2ª'!R14 -> - | Y65: ='2ª'!S14 -> - | ... AA65: ='2ª'!U14 -> 0 | AB65: 2ª série EJA | AD65: 2º SEMESTRE
A66: =RIGHT('[1]2ª'!$A$5:$D$5,12) -> 2ª SÉRIE E.F | B66: 10 | C66: ='2ª'!$B15 -> 0 | D66: ='2ª'!$C15 -> 0 | E66: ='2ª'!$D15 -> 0 | F66: ='2ª'!$E15 | G66: ='2ª'!$F15 -> 0 | H66: ='2ª'!$G15 -> 0 | I66: ='2ª'!$H15 -> 0 | K66: ='2ª'!$I15 -> 0 | L66: ='2ª'!$J15 | N66: ='2ª'!$K15 | P66: 19:00 às 23:00 | Q66: Terça e Quinta-feira 19h00 - 20h00 | R66: ='2ª'!L15 -> Não | S66: ='2ª'!M15 -> Eliane | T66: ='2ª'!N15 -> - | U66: ='2ª'!O15 -> - | V66: ='2ª'!P15 -> - | W66: ='2ª'!Q15 -> - | X66: ='2ª'!R15 -> - | Y66: ='2ª'!S15 -> - | ... AA66: ='2ª'!U15 -> 0 | AB66: 2ª série EJA | AD66: 2º SEMESTRE
A67: =RIGHT('[1]2ª'!$A$5:$D$5,12) -> 2ª SÉRIE E.F | B67: 11 | C67: ='2ª'!$B16 -> 0 | D67: ='2ª'!$C16 -> 0 | E67: ='2ª'!$D16 -> 0 | F67: ='2ª'!$E16 | G67: ='2ª'!$F16 -> 0 | H67: ='2ª'!$G16 -> 0 | I67: ='2ª'!$H16 -> 0 | K67: ='2ª'!$I16 -> 0 | L67: ='2ª'!$J16 | N67: ='2ª'!$K16 | P67: 19:00 às 23:00 | Q67: Terça e Quinta-feira 19h00 - 20h00 | R67: ='2ª'!L16 -> Não | S67: ='2ª'!M16 -> Eliane | T67: ='2ª'!N16 -> - | U67: ='2ª'!O16 -> - | V67: ='2ª'!P16 -> - | W67: ='2ª'!Q16 -> - | X67: ='2ª'!R16 -> - | Y67: ='2ª'!S16 -> - | ... AA67: ='2ª'!U16 -> 0 | AB67: 2ª série EJA | AD67: 2º SEMESTRE
A68: =RIGHT('[1]2ª'!$A$5:$D$5,12) -> 2ª SÉRIE E.F | B68: 12 | C68: ='2ª'!$B17 -> 0 | D68: ='2ª'!$C17 -> 0 | E68: ='2ª'!$D17 -> 0 | F68: ='2ª'!$E17 | G68: ='2ª'!$F17 -> 0 | H68: ='2ª'!$G17 -> 0 | I68: ='2ª'!$H17 -> 0 | K68: ='2ª'!$I17 -> 0 | L68: ='2ª'!$J17 | N68: ='2ª'!$K17 | P68: 19:00 às 23:00 | Q68: Terça e Quinta-feira 19h00 - 20h00 | R68: ='2ª'!L17 -> Não | S68: ='2ª'!M17 -> Eliane | T68: ='2ª'!N17 -> - | U68: ='2ª'!O17 -> - | V68: ='2ª'!P17 -> - | W68: ='2ª'!Q17 -> - | X68: ='2ª'!R17 -> - | Y68: ='2ª'!S17 -> - | ... AA68: ='2ª'!U17 -> 0 | AB68: 2ª série EJA | AD68: 2º SEMESTRE
A69: =RIGHT('[1]2ª'!$A$5:$D$5,12) -> 2ª SÉRIE E.F | B69: 13 | C69: ='2ª'!$B18 -> 0 | D69: ='2ª'!$C18 -> 0 | E69: ='2ª'!$D18 -> 0 | F69: ='2ª'!$E18 | G69: ='2ª'!$F18 -> 0 | H69: ='2ª'!$G18 -> 0 | I69: ='2ª'!$H18 -> 0 | K69: ='2ª'!$I18 -> 0 | L69: ='2ª'!$J18 | N69: ='2ª'!$K18 | P69: 19:00 às 23:00 | Q69: Terça e Quinta-feira 19h00 - 20h00 | R69: ='2ª'!L18 -> Não | S69: ='2ª'!M18 -> Eliane | T69: ='2ª'!N18 -> - | U69: ='2ª'!O18 -> - | V69: ='2ª'!P18 -> - | W69: ='2ª'!Q18 -> - | X69: ='2ª'!R18 -> - | Y69: ='2ª'!S18 -> - | ... AA69: ='2ª'!U18 -> 0 | AB69: 2ª série EJA | AD69: 2º SEMESTRE
A70: =RIGHT('[1]2ª'!$A$5:$D$5,12) -> 2ª SÉRIE E.F | B70: 14 | C70: ='2ª'!$B19 -> 0 | D70: ='2ª'!$C19 -> 0 | E70: ='2ª'!$D19 -> 0 | F70: ='2ª'!$E19 | G70: ='2ª'!$F19 -> 0 | H70: ='2ª'!$G19 -> 0 | I70: ='2ª'!$H19 -> 0 | K70: ='2ª'!$I19 -> 0 | L70: ='2ª'!$J19 | N70: ='2ª'!$K19 | P70: 19:00 às 23:00 | Q70: Terça e Quinta-feira 19h00 - 20h00 | R70: ='2ª'!L19 -> Não | S70: ='2ª'!M19 -> Eliane | T70: ='2ª'!N19 -> - | U70: ='2ª'!O19 -> - | V70: ='2ª'!P19 -> - | W70: ='2ª'!Q19 -> - | X70: ='2ª'!R19 -> - | Y70: ='2ª'!S19 -> - | ... AA70: ='2ª'!U19 -> 0 | AB70: 2ª série EJA | AD70: 2º SEMESTRE
... A111: =RIGHT('[1]2ª'!$A$5:$D$5,12) -> 2ª SÉRIE E.F | B111: 55 | C111: ='2ª'!$B60 -> 0 | D111: ='2ª'!$C60 -> 0 | E111: ='2ª'!$D60 -> 0 | F111: ='2ª'!$E60 -> 0 | G111: ='2ª'!$F60 -> 0 | H111: ='2ª'!$G60 -> 0 | I111: ='2ª'!$H60 -> 0 | K111: ='2ª'!$I60 -> 0 | L111: ='2ª'!$J60 -> 0 | N111: ='2ª'!$K60 -> 0 | P111: 19:00 às 23:00 | Q111: Terça e Quinta-feira 19h00 - 20h00 | R111: ='2ª'!L60 -> 0 | S111: ='2ª'!M60 -> 0 | T111: ='2ª'!N60 -> 0 | U111: ='2ª'!O60 -> 0 | V111: ='2ª'!P60 -> 0 | W111: ='2ª'!Q60 -> 0 | X111: ='2ª'!R60 -> 0 | Y111: ='2ª'!S60 -> 0 | ... AA111: ='2ª'!U60 -> 0 | AB111: 2ª série EJA | AD111: 2º SEMESTRE
A112: =RIGHT('[1]3ª'!$A$5:$D$5,12) -> 3ª SÉRIE E.F | B112: 1 | C112: ='3ª'!$B7 -> 18767 | D112: ='3ª'!$C7 -> CLAUDEMIR JOSE DE AMORIM | E112: ='3ª'!$D7 -> M | F112: ='3ª'!$E7 -> MA | G112: ='3ª'!$F7 -> 24673 | H112: ='3ª'!$G7 -> 0 | I112: ='3ª'!$H7 -> 69889673-7 | K112: ='3ª'!$I7 -> 0 | L112: ='3ª'!$J7 -> DISP.IDADE | N112: ='3ª'!$K7 -> 58 | P112: 19:00 às 23:00 | Q112: Terça e Quinta-feira 19h00 - 20h00 | R112: ='3ª'!$L7 -> Não | S112: ='3ª'!$M7 -> Eliane | T112: ='3ª'!$N7 -> - | U112: ='3ª'!$O7 -> - | V112: ='3ª'!$P7 -> - | W112: ='3ª'!$Q7 -> - | X112: ='3ª'!$R7 -> - | Y112: ='3ª'!$S7 -> - | Z112: ='3ª'!$T7 -> 0 | AA112: ='3ª'!$U7 -> 0 | AB112: 3ª série EJA | AD112: 2º SEMESTRE
A113: =RIGHT('[1]3ª'!$A$5:$D$5,12) -> 3ª SÉRIE E.F | B113: 2 | C113: ='3ª'!$B8 -> 18837 | D113: ='3ª'!$C8 -> DIEGO RYAN SANTOS DE ALCANTARA | E113: ='3ª'!$D8 -> M | F113: ='3ª'!$E8 -> MA | G113: ='3ª'!$F8 -> 40045 | H113: ='3ª'!$G8 -> 111223789-6 | I113: ='3ª'!$H8 -> 0 | K113: ='3ª'!$I8 -> 0 | L113: ='3ª'!$J8 | N113: ='3ª'!$K8 -> 16 | P113: 19:00 às 23:00 | Q113: Terça e Quinta-feira 19h00 - 20h00 | R113: ='3ª'!$L8 -> Não | S113: ='3ª'!$M8 -> Eliane | T113: ='3ª'!$N8 -> - | U113: ='3ª'!$O8 -> - | V113: ='3ª'!$P8 -> - | W113: ='3ª'!$Q8 -> - | X113: ='3ª'!$R8 -> - | Y113: ='3ª'!$S8 -> - | Z113: ='3ª'!$T8 -> 0 | AA113: ='3ª'!$U8 -> 0 | AB113: 3ª série EJA | AD113: 2º SEMESTRE
A114: =RIGHT('[1]3ª'!$A$5:$D$5,12) -> 3ª SÉRIE E.F | B114: 3 | C114: ='3ª'!$B9 -> 17989 | D114: ='3ª'!$C9 -> ELISA DA COSTA BARRETO | E114: ='3ª'!$D9 -> F | F114: ='3ª'!$E9 -> MC | G114: ='3ª'!$F9 -> 24447 | H114: ='3ª'!$G9 -> 124351785-2 | I114: ='3ª'!$H9 -> 52171529-5 | K114: ='3ª'!$I9 -> MC - 20/08 | L114: ='3ª'!$J9 -> DISP.IDADE | N114: ='3ª'!$K9 -> 58 | P114: 19:00 às 23:00 | Q114: Terça e Quinta-feira 19h00 - 20h00 | R114: ='3ª'!$L9 -> Não | S114: ='3ª'!$M9 -> Eliane | T114: ='3ª'!$N9 -> - | U114: ='3ª'!$O9 -> - | V114: ='3ª'!$P9 -> - | W114: ='3ª'!$Q9 -> - | X114: ='3ª'!$R9 -> - | Y114: ='3ª'!$S9 -> - | Z114: ='3ª'!$T9 -> Sem Informação | AA114: ='3ª'!$U9 -> MC por Solicitação do Responsavel | AB114: 3ª série EJA | AD114: 2º SEMESTRE
A115: =RIGHT('[1]3ª'!$A$5:$D$5,12) -> 3ª SÉRIE E.F | B115: 4 | C115: ='3ª'!$B10 -> 18839 | D115: ='3ª'!$C10 -> JOSE MIGUEL DA SILVA FILHO | E115: ='3ª'!$D10 -> M | F115: ='3ª'!$E10 -> MA | G115: ='3ª'!$F10 -> 26939 | H115: ='3ª'!$G10 -> 0 | I115: ='3ª'!$H10 -> 26885705 | K115: ='3ª'!$I10 -> 0 | L115: ='3ª'!$J10 -> DISP.IDADE | N115: ='3ª'!$K10 -> 51 | P115: 19:00 às 23:00 | Q115: Terça e Quinta-feira 19h00 - 20h00 | R115: ='3ª'!$L10 -> Não | S115: ='3ª'!$M10 -> Eliane | T115: ='3ª'!$N10 -> - | U115: ='3ª'!$O10 -> - | V115: ='3ª'!$P10 -> - | W115: ='3ª'!$Q10 -> - | X115: ='3ª'!$R10 -> - | Y115: ='3ª'!$S10 -> - | Z115: ='3ª'!$T10 -> 0 | AA115: ='3ª'!$U10 -> 0 | AB115: 3ª série EJA | AD115: 2º SEMESTRE
A116: =RIGHT('[1]3ª'!$A$5:$D$5,12) -> 3ª SÉRIE E.F | B116: 5 | C116: ='3ª'!$B11 -> 18357 | D116: ='3ª'!$C11 -> JOSETE FERREIRA DAMIAO DA SILVA | E116: ='3ª'!$D11 -> F | F116: ='3ª'!$E11 -> MC | G116: ='3ª'!$F11 -> 23056 | H116: ='3ª'!$G11 -> 0 | I116: ='3ª'!$H11 -> 67130928-6 | K116: ='3ª'!$I11 -> MC - 05/08 | L116: ='3ª'!$J11 -> DISP.IDADE | N116: ='3ª'!$K11 -> 62 | P116: 19:00 às 23:00 | Q116: Terça e Quinta-feira 19h00 - 20h00 | R116: ='3ª'!$L11 -> Não | S116: ='3ª'!$M11 -> Eliane | T116: ='3ª'!$N11 -> - | U116: ='3ª'!$O11 -> - | V116: ='3ª'!$P11 -> - | W116: ='3ª'!$Q11 -> - | X116: ='3ª'!$R11 -> - | Y116: ='3ª'!$S11 -> - | Z116: ='3ª'!$T11 -> Sem Informação | AA116: ='3ª'!$U11 -> MC por Solicitação do Responsavel | AB116: 3ª série EJA | AD116: 2º SEMESTRE
A117: =RIGHT('[1]3ª'!$A$5:$D$5,12) -> 3ª SÉRIE E.F | B117: 6 | C117: ='3ª'!$B12 -> 18747 | D117: ='3ª'!$C12 -> MARIA LUCIA LEITE DE OLIVEIRA | E117: ='3ª'!$D12 -> F | F117: ='3ª'!$E12 -> MA | G117: ='3ª'!$F12 -> 21869 | H117: ='3ª'!$G12 -> 0 | I117: ='3ª'!$H12 -> 131542312 | K117: ='3ª'!$I12 -> 0 | L117: ='3ª'!$J12 -> DISP.IDADE | N117: ='3ª'!$K12 -> 65 | P117: 19:00 às 23:00 | Q117: Terça e Quinta-feira 19h00 - 20h00 | R117: ='3ª'!$L12 -> Não | S117: ='3ª'!$M12 -> Eliane | T117: ='3ª'!$N12 -> - | U117: ='3ª'!$O12 -> - | V117: ='3ª'!$P12 -> - | W117: ='3ª'!$Q12 -> - | X117: ='3ª'!$R12 -> - | Y117: ='3ª'!$S12 -> - | Z117: ='3ª'!$T12 -> 0 | AA117: ='3ª'!$U12 -> 0 | AB117: 3ª série EJA | AD117: 2º SEMESTRE
A118: =RIGHT('[1]3ª'!$A$5:$D$5,12) -> 3ª SÉRIE E.F | B118: 7 | C118: ='3ª'!$B13 -> 18906 | D118: ='3ª'!$C13 -> MYKAELLY CRISTINA CARVALHO CAMPOS | E118: ='3ª'!$D13 -> F | F118: ='3ª'!$E13 -> MA | G118: ='3ª'!$F13 -> 40161 | H118: ='3ª'!$G13 -> 113758780-5 | I118: ='3ª'!$H13 -> 0 | K118: ='3ª'!$I13 -> 0 | L118: ='3ª'!$J13 | N118: ='3ª'!$K13 -> 15 | P118: 19:00 às 23:00 | Q118: Terça e Quinta-feira 19h00 - 20h00 | R118: ='3ª'!$L13 -> Não | S118: ='3ª'!$M13 -> Eliane | T118: ='3ª'!$N13 -> - | U118: ='3ª'!$O13 -> - | V118: ='3ª'!$P13 -> - | W118: ='3ª'!$Q13 -> - | X118: ='3ª'!$R13 -> - | Y118: ='3ª'!$S13 -> - | Z118: ='3ª'!$T13 -> 0 | AA118: ='3ª'!$U13 -> 0 | AB118: 3ª série EJA | AD118: 2º SEMESTRE
A119: =RIGHT('[1]3ª'!$A$5:$D$5,12) -> 3ª SÉRIE E.F | B119: 8 | C119: ='3ª'!$B14 -> 0 | D119: ='3ª'!$C14 -> 0 | E119: ='3ª'!$D14 -> 0 | F119: ='3ª'!$E14 | G119: ='3ª'!$F14 -> 0 | H119: ='3ª'!$G14 -> 0 | I119: ='3ª'!$H14 -> 0 | K119: ='3ª'!$I14 -> 0 | L119: ='3ª'!$J14 | N119: ='3ª'!$K14 | P119: 19:00 às 23:00 | Q119: Terça e Quinta-feira 19h00 - 20h00 | R119: ='3ª'!$L14 -> Não | S119: ='3ª'!$M14 -> Eliane | T119: ='3ª'!$N14 -> - | U119: ='3ª'!$O14 -> - | V119: ='3ª'!$P14 -> - | W119: ='3ª'!$Q14 -> - | X119: ='3ª'!$R14 -> - | Y119: ='3ª'!$S14 -> - | Z119: ='3ª'!$T14 -> 0 | AA119: ='3ª'!$U14 -> 0 | AB119: 3ª série EJA | AD119: 2º SEMESTRE
A120: =RIGHT('[1]3ª'!$A$5:$D$5,12) -> 3ª SÉRIE E.F | B120: 9 | C120: ='3ª'!$B15 -> 0 | D120: ='3ª'!$C15 -> 0 | E120: ='3ª'!$D15 -> 0 | F120: ='3ª'!$E15 | G120: ='3ª'!$F15 -> 0 | H120: ='3ª'!$G15 -> 0 | I120: ='3ª'!$H15 -> 0 | K120: ='3ª'!$I15 -> 0 | L120: ='3ª'!$J15 | N120: ='3ª'!$K15 | P120: 19:00 às 23:00 | Q120: Terça e Quinta-feira 19h00 - 20h00 | R120: ='3ª'!$L15 -> Não | S120: ='3ª'!$M15 -> Eliane | T120: ='3ª'!$N15 -> - | U120: ='3ª'!$O15 -> - | V120: ='3ª'!$P15 -> - | W120: ='3ª'!$Q15 -> - | X120: ='3ª'!$R15 -> - | Y120: ='3ª'!$S15 -> - | Z120: ='3ª'!$T15 -> 0 | AA120: ='3ª'!$U15 -> 0 | AB120: 3ª série EJA | AD120: 2º SEMESTRE
...

Sheet Total de Alunos
C1: 1302 | D1: =32+32+32+29 -> 125 | F1: =C1+D1 -> 1427 | H1: 2012
E2: saldo
B3: Dados Gerais dos alunos da U.E. durante o ano letivo 1º Semestre de 2025
B4: SALA | D4: ANO | E4: MATRICULAS ATIVAS (MA) | H4: MATRÍCULAS CANCELADAS (MC) | K4: INCLUSÃO | N4: DISP.ED.FÍS.
E5: Masc. | F5: Fem. | G5: Total | H5: Masc. | I5: Fem. | J5: Total | K5: Masc. | L5: Fem. | M5: Total | N5: Masc. | O5: Fem. | P5: Total
D6: 1ª | E6: =COUNTIFS('1ª'!D:D,"M",'1ª'!E:E,"MA") -> 0 | F6: =COUNTIFS('1ª'!D:D,"F",'1ª'!E:E,"MA") -> 3 | G6: =SUM(E6:F6) -> 3 | H6: =COUNTIFS('1ª'!D:D,"M",'1ª'!E:E,"MC") -> 0 | I6: =COUNTIFS('1ª'!D:D,"F",'1ª'!E:E,"MC") -> 0 | J6: =SUM(H6:I6) -> 0 | K6: {=SUMPRODUCT((('1ª'!D:D="M")*('1ª'!E:E="MA")*(ISNUMBER(SEARCH("INCLUS",UPPER('1ª'!I:I))))))} -> 0 | L6: {=SUMPRODUCT((('1ª'!D:D="F")*('1ª'!E:E="MA")*(ISNUMBER(SEARCH("INCLUS",UPPER('1ª'!I:I))))))} -> 0 | M6: =SUM(K6:L6) -> 0 | N6: {=SUMPRODUCT((('1ª'!D:D="M")*('1ª'!E:E="MA")*(ISNUMBER(SEARCH("DISP",UPPER('1ª'!J:J))))))} -> 0 | O6: {=SUMPRODUCT((('1ª'!D:D="F")*('1ª'!E:E="MA")*(ISNUMBER(SEARCH("DISP",UPPER('1ª'!J:J))))))} -> 3 | P6: =SUM(N6:O6) -> 3
D7: 2ª | E7: =COUNTIFS('2ª'!D:D,"M",'2ª'!E:E,"MA") -> 1 | F7: =COUNTIFS('2ª'!D:D,"F",'2ª'!E:E,"MA") -> 3 | G7: =SUM(E7:F7) -> 4 | H7: =COUNTIFS('2ª'!D:D,"M",'2ª'!E:E,"MC") -> 0 | I7: =COUNTIFS('2ª'!D:D,"F",'2ª'!E:E,"MC") -> 0 | J7: =SUM(H7:I7) -> 0 | K7: {=SUMPRODUCT((('2ª'!D:D="M")*('2ª'!E:E="MA")*(ISNUMBER(SEARCH("INCLUS",UPPER('2ª'!I:I))))))} -> 0 | L7: {=SUMPRODUCT((('2ª'!D:D="F")*('2ª'!E:E="MA")*(ISNUMBER(SEARCH("INCLUS",UPPER('2ª'!I:I))))))} -> 0 | M7: =SUM(K7:L7) -> 0 | N7: {=SUMPRODUCT((('2ª'!D:D="M")*('2ª'!E:E="MA")*(ISNUMBER(SEARCH("DISP",UPPER('2ª'!J:J))))))} -> 1 | O7: {=SUMPRODUCT((('2ª'!D:D="F")*('2ª'!E:E="MA")*(ISNUMBER(SEARCH("DISP",UPPER('2ª'!J:J))))))} -> 3 | P7: =SUM(N7:O7) -> 4
D8: 3ª | E8: =COUNTIFS('3ª'!D:D,"M",'3ª'!E:E,"MA") -> 3 | F8: =COUNTIFS('3ª'!D:D,"F",'3ª'!E:E,"MA") -> 2 | G8: =SUM(E8:F8) -> 5 | H8: =COUNTIFS('3ª'!D:D,"M",'3ª'!E:E,"MC") -> 0 | I8: =COUNTIFS('3ª'!D:D,"F",'3ª'!E:E,"MC") -> 2 | J8: =SUM(H8:I8) -> 2 | K8: {=SUMPRODUCT((('3ª'!D:D="M")*('3ª'!E:E="MA")*(ISNUMBER(SEARCH("INCLUS",UPPER('3ª'!I:I))))))} -> 0 | L8: {=SUMPRODUCT((('3ª'!D:D="F")*('3ª'!E:E="MA")*(ISNUMBER(SEARCH("INCLUS",UPPER('3ª'!I:I))))))} -> 0 | M8: =SUM(K8:L8) -> 0 | N8: {=SUMPRODUCT((('3ª'!D:D="M")*('3ª'!E:E="MA")*(ISNUMBER(SEARCH("DISP",UPPER('3ª'!J:J))))))} -> 2 | O8: {=SUMPRODUCT((('3ª'!D:D="F")*('3ª'!E:E="MA")*(ISNUMBER(SEARCH("DISP",UPPER('3ª'!J:J))))))} -> 1 | P8: =SUM(N8:O8) -> 3
D9: 4ª | E9: =COUNTIFS('4ª'!D:D,"M",'4ª'!E:E,"MA") -> 3 | F9: =COUNTIFS('4ª'!D:D,"F",'4ª'!E:E,"MA") -> 7 | G9: =SUM(E9:F9) -> 10 | H9: =COUNTIFS('4ª'!D:D,"M",'4ª'!E:E,"MC") -> 1 | I9: =COUNTIFS('4ª'!D:D,"F",'4ª'!E:E,"MC") -> 2 | J9: =SUM(H9:I9) -> 3 | K9: {=SUMPRODUCT((('4ª'!D:D="M")*('4ª'!E:E="MA")*(ISNUMBER(SEARCH("INCLUS",UPPER('4ª'!I:I))))))} -> 0 | L9: {=SUMPRODUCT((('4ª'!D:D="F")*('4ª'!E:E="MA")*(ISNUMBER(SEARCH("INCLUS",UPPER('4ª'!I:I))))))} -> 0 | M9: =SUM(K9:L9) -> 0 | N9: {=SUMPRODUCT((('4ª'!D:D="M")*('4ª'!E:E="MA")*(ISNUMBER(SEARCH("DISP",UPPER('4ª'!J:J))))))} -> 2 | O9: {=SUMPRODUCT((('4ª'!D:D="F")*('4ª'!E:E="MA")*(ISNUMBER(SEARCH("DISP",UPPER('4ª'!J:J))))))} -> 6 | P9: =SUM(N9:O9) -> 8
E10: =SUM(E6:E9) -> 7 | F10: =SUM(F6:F9) -> 15 | G10: =SUM(E10:F10) -> 22 | H10: =SUM(H6:H9) -> 1 | I10: =SUM(I6:I9) -> 4 | J10: =SUM(J6:J9) -> 5 | K10: =SUM(K6:K9) -> 0 | L10: =SUM(L6:L9) -> 0 | M10: =SUM(M6:M9) -> 0 | N10: =SUM(N6:N9) -> 5 | O10: =SUM(O6:O9) -> 13 | P10: =SUM(P6:P9) -> 18
D11: 5ª | E11: =COUNTIFS('5ª'!D:D,"M",'5ª'!E:E,"MA") -> 3 | F11: =COUNTIFS('5ª'!D:D,"F",'5ª'!E:E,"MA") -> 4 | G11: =SUM(E11:F11) -> 7 | H11: =COUNTIFS('5ª'!D:D,"M",'5ª'!E:E,"MC") -> 0 | I11: =COUNTIFS('5ª'!D:D,"F",'5ª'!E:E,"MC") -> 1 | J11: =SUM(H11:I11) -> 1 | K11: {=SUMPRODUCT((('5ª'!D:D="M")*('5ª'!E:E="MA")*(ISNUMBER(SEARCH("INCLUS",UPPER('5ª'!I:I))))))} -> 0 | L11: {=SUMPRODUCT((('5ª'!D:D="F")*('5ª'!E:E="MA")*(ISNUMBER(SEARCH("INCLUS",UPPER('5ª'!I:I))))))} -> 0 | M11: =SUM(K11:L11) -> 0 | N11: {=SUMPRODUCT((('5ª'!D:D="M")*('5ª'!E:E="MA")*(ISNUMBER(SEARCH("DISP",UPPER('5ª'!J:J))))))} -> 2 | O11: {=SUMPRODUCT((('5ª'!D:D="F")*('5ª'!E:E="MA")*(ISNUMBER(SEARCH("DISP",UPPER('5ª'!J:J))))))} -> 4 | P11: =SUM(N11:O11) -> 6
D12: 6ª | E12: =COUNTIFS('6ª'!D:D,"M",'6ª'!E:E,"MA") -> 5 | F12: =COUNTIFS('6ª'!D:D,"F",'6ª'!E:E,"MA") -> 4 | G12: =SUM(E12:F12) -> 9 | H12: =COUNTIFS('6ª'!D:D,"M",'6ª'!E:E,"MC") -> 0 | I12: =COUNTIFS('6ª'!D:D,"F",'6ª'!E:E,"MC") -> 1 | J12: =SUM(H12:I12) -> 1 | K12: {=SUMPRODUCT((('6ª'!D:D="M")*('6ª'!E:E="MA")*(ISNUMBER(SEARCH("INCLUS",UPPER('6ª'!I:I))))))} -> 0 | L12: {=SUMPRODUCT((('6ª'!D:D="F")*('6ª'!E:E="MA")*(ISNUMBER(SEARCH("INCLUS",UPPER('6ª'!I:I))))))} -> 0 | M12: =SUM(K12:L12) -> 0 | N12: {=SUMPRODUCT((('6ª'!D:D="M")*('6ª'!E:E="MA")*(ISNUMBER(SEARCH("DISP",UPPER('6ª'!J:J))))))} -> 4 | O12: {=SUMPRODUCT((('6ª'!D:D="F")*('6ª'!E:E="MA")*(ISNUMBER(SEARCH("DISP",UPPER('6ª'!J:J))))))} -> 3 | P12: =SUM(N12:O12) -> 7
D13: 7ª | E13: =COUNTIFS('7ª'!D:D,"M",'7ª'!E:E,"MA") -> 7 | F13: =COUNTIFS('7ª'!D:D,"F",'7ª'!E:E,"MA") -> 5 | G13: =SUM(E13:F13) -> 12 | H13: =COUNTIFS('7ª'!D:D,"M",'7ª'!E:E,"MC") -> 0 | I13: =COUNTIFS('7ª'!D:D,"F",'7ª'!E:E,"MC") -> 1 | J13: =SUM(H13:I13) -> 1 | K13: {=SUMPRODUCT((('7ª'!D:D="M")*('7ª'!E:E="MA")*(ISNUMBER(SEARCH("INCLUS",UPPER('7ª'!I:I))))))} -> 1 | L13: {=SUMPRODUCT((('7ª'!D:D="F")*('7ª'!E:E="MA")*(ISNUMBER(SEARCH("INCLUS",UPPER('7ª'!I:I))))))} -> 0 | M13: =SUM(K13:L13) -> 1 | N13: {=SUMPRODUCT((('7ª'!D:D="M")*('7ª'!E:E="MA")*(ISNUMBER(SEARCH("DISP",UPPER('7ª'!J:J))))))} -> 2 | O13: {=SUMPRODUCT((('7ª'!D:D="F")*('7ª'!E:E="MA")*(ISNUMBER(SEARCH("DISP",UPPER('7ª'!J:J))))))} -> 2 | P13: =SUM(N13:O13) -> 4
D14: 8ª | E14: =COUNTIFS('8ª'!D:D,"M",'8ª'!E:E,"MA") -> 8 | F14: =COUNTIFS('8ª'!D:D,"F",'8ª'!E:E,"MA") -> 12 | G14: =SUM(E14:F14) -> 20 | H14: =COUNTIFS('8ª'!D:D,"M",'8ª'!E:E,"MC") -> 0 | I14: =COUNTIFS('8ª'!D:D,"F",'8ª'!E:E,"MC") -> 0 | J14: =SUM(H14:I14) -> 0 | K14: {=SUMPRODUCT((('8ª'!D:D="M")*('8ª'!E:E="MA")*(ISNUMBER(SEARCH("INCLUS",UPPER('8ª'!I:I))))))} -> 1 | L14: {=SUMPRODUCT((('8ª'!D:D="F")*('8ª'!E:E="MA")*(ISNUMBER(SEARCH("INCLUS",UPPER('8ª'!I:I))))))} -> 0 | M14: =SUM(K14:L14) -> 1 | N14: {=SUMPRODUCT((('8ª'!D:D="M")*('8ª'!E:E="MA")*(ISNUMBER(SEARCH("DISP",UPPER('8ª'!J:J))))))} -> 0 | O14: {=SUMPRODUCT((('8ª'!D:D="F")*('8ª'!E:E="MA")*(ISNUMBER(SEARCH("DISP",UPPER('8ª'!J:J))))))} -> 7 | P14: =SUM(N14:O14) -> 7
E15: =SUM(E11:E14) -> 23 | F15: =SUM(F11:F14) -> 25 | G15: =SUM(G11:G14) -> 48 | H15: =SUM(H11:H14) -> 0 | I15: =SUM(I11:I14) -> 3 | J15: =SUM(J11:J14) -> 3 | K15: =SUM(K11:K14) -> 2 | L15: =SUM(L11:L14) -> 0 | ... P15: =SUM(P11:P14) -> 24
D16: 1ª EM | E16: =COUNTIFS('1ª EM'!D:D,"M",'1ª EM'!E:E,"MA") -> 13 | F16: =COUNTIFS('1ª EM'!D:D,"F",'1ª EM'!E:E,"MA") -> 13 | G16: =SUM(E16:F16) -> 26 | H16: =COUNTIFS('1ª EM'!D:D,"M",'1ª EM'!E:E,"MC") -> 0 | I16: =COUNTIFS('1ª EM'!D:D,"F",'1ª EM'!E:E,"MC") -> 1 | J16: =SUM(H16:I16) -> 1 | K16: {=SUMPRODUCT((('1ª EM'!D:D="M")*('1ª EM'!E:E="MA")*(ISNUMBER(SEARCH("INCLUS",UPPER('1ª EM'!I:I))))))} -> 0 | L16: {=SUMPRODUCT((('1ª EM'!D:D="F")*('1ª EM'!E:E="MA")*(ISNUMBER(SEARCH("INCLUS",UPPER('1ª EM'!I:I))))))} -> 0 | M16: =SUM(K16:L16) -> 0 | N16: {=SUMPRODUCT((('1ª EM'!D:D="M")*('1ª EM'!E:E="MA")*(ISNUMBER(SEARCH("DISP",UPPER('1ª EM'!J:J))))))} -> 5 | O16: {=SUMPRODUCT((('1ª EM'!D:D="F")*('1ª EM'!E:E="MA")*(ISNUMBER(SEARCH("DISP",UPPER('1ª EM'!J:J))))))} -> 10 | P16: =SUM(N16:O16) -> 15
D17: 2ª EM | E17: =COUNTIFS('2ª EM'!D:D,"M",'2ª EM'!E:E,"MA") -> 11 | F17: =COUNTIFS('2ª EM'!D:D,"F",'2ª EM'!E:E,"MA") -> 9 | G17: =SUM(E17:F17) -> 20 | H17: =COUNTIFS('2ª EM'!D:D,"M",'2ª EM'!E:E,"MC") -> 0 | I17: =COUNTIFS('2ª EM'!D:D,"F",'2ª EM'!E:E,"MC") -> 0 | J17: =SUM(H17:I17) -> 0 | K17: {=SUMPRODUCT((('2ª EM'!D:D="M")*('2ª EM'!E:E="MA")*(ISNUMBER(SEARCH("INCLUS",UPPER('2ª EM'!I:I))))))} -> 1 | L17: {=SUMPRODUCT((('2ª EM'!D:D="F")*('2ª EM'!E:E="MA")*(ISNUMBER(SEARCH("INCLUS",UPPER('2ª EM'!I:I))))))} -> 0 | M17: =SUM(K17:L17) -> 1 | N17: {=SUMPRODUCT((('2ª EM'!D:D="M")*('2ª EM'!E:E="MA")*(ISNUMBER(SEARCH("DISP",UPPER('2ª EM'!J:J))))))} -> 7 | O17: {=SUMPRODUCT((('2ª EM'!D:D="F")*('2ª EM'!E:E="MA")*(ISNUMBER(SEARCH("DISP",UPPER('2ª EM'!J:J))))))} -> 5 | P17: =SUM(N17:O17) -> 12
D18: 3ª EM | E18: =COUNTIFS('3ª EM'!D:D,"M",'3ª EM'!E:E,"MA") -> 14 | F18: =COUNTIFS('3ª EM'!D:D,"F",'3ª EM'!E:E,"MA") -> 20 | G18: =SUM(E18:F18) -> 34 | H18: =COUNTIFS('3ª EM'!D:D,"M",'3ª EM'!E:E,"MC") -> 1 | I18: =COUNTIFS('3ª EM'!D:D,"F",'3ª EM'!E:E,"MC") -> 1 | J18: =SUM(H18:I18) -> 2 | K18: {=SUMPRODUCT((('3ª EM'!D:D="M")*('3ª EM'!E:E="MA")*(ISNUMBER(SEARCH("INCLUS",UPPER('3ª EM'!I:I))))))} -> 1 | L18: {=SUMPRODUCT((('3ª EM'!D:D="F")*('3ª EM'!E:E="MA")*(ISNUMBER(SEARCH("INCLUS",UPPER('3ª EM'!I:I))))))} -> 0 | M18: =SUM(K18:L18) -> 1 | N18: {=SUMPRODUCT((('3ª EM'!D:D="M")*('3ª EM'!E:E="MA")*(ISNUMBER(SEARCH("DISP",UPPER('3ª EM'!J:J))))))} -> 3 | O18: {=SUMPRODUCT((('3ª EM'!D:D="F")*('3ª EM'!E:E="MA")*(ISNUMBER(SEARCH("DISP",UPPER('3ª EM'!J:J))))))} -> 12 | P18: =SUM(N18:O18) -> 15
E19: =SUM(E16:E18) -> 38 | F19: =SUM(F16:F18) -> 42 | G19: =SUM(E19:F19) -> 80 | H19: =SUM(H16:H18) -> 1 | I19: =SUM(I16:I18) -> 2 | J19: =SUM(J16:J18) -> 3 | K19: =SUM(K16:K18) -> 2 | L19: =SUM(L16:L18) -> 0 | M19: =SUM(M16:M18) -> 2 | N19: =SUM(N16:N18) -> 15 | O19: =SUM(O16:O18) -> 27 | P19: =SUM(P16:P18) -> 42
B20: TOTAL | E20: =SUM(E10,E15,E19) -> 68 | F20: =SUM(F10,F15,F19) -> 82 | G20: =SUM(G10,G15,G19) -> 150 | H20: =SUM(H10,H15,H19) -> 2 | I20: =SUM(I10,I15,I19) -> 9 | J20: =SUM(J10,J15,J19) -> 11 | K20: =SUM(K10+K15+K19) -> 4 | L20: =SUM(L10+L15+L19) -> 0 | M20: =SUM(M10,M15,M19) -> 4 | N20: =SUM(N10,N15,N19) -> 28 | O20: =SUM(O10,O15,O19) -> 56 | P20: =SUM(P10,P15,P19) -> 84
E21: Masc. | F21: Fem. | G21: Total | H21: Masc. | I21: Fem. | J21: Total | K21: Masc. | L21: Fem. | M21: Total | N21: Masc. | O21: Fem. | P21: Total
E22: MATRICULAS ATIVAS (MA) | H22: MATRÍCULAS CANCELADAS (MC) | K22: INCLUSÃO | N22: DISP.ED.FÍS.

Sheet 1ª
C1: Município da Estância Balneária de Praia Grande
C2: Estado de São Paulo
C3: E.M. José Padin Mouta
C4: EDUCAÇÃO DE JOVENS DE ADULTOS - EJA - 2º Sem/2025
A5: SÉRIE: 1ª SÉRIE E.F | D5: SALA: | G5: DATA IMPRESSÃO: | H5: =TODAY() -> 45931 | I5: NR. Classe: SED:
A6: Nº | B6: RM | C6: NOME DO ALUNO | D6: S | E6: COD | F6: NASC. | G6: RA | H6: RG | I6: OBS.: | J6: ED. FÍSICA | K6: IDADE | L6: INCLUSÃO | M6: PROFESSOR | N6: PLANO DE AÇÃO | O6: AEE | P6: DEFICIENCIA | Q6: OBS DEFICIENCIA: | R6: C. RODAS | S6: ADEQUAÇÕES | T6: TIPO TE | U6: LOCAL TE | V6: CPF
A7: 1 | B7: 16345 | C7: ELAINE FRANCISCO DE QUEIROZ | D7: F | E7: =IF(COUNTIF(I7,"*MC*")=1,"MC",IF(COUNTIF(I7,"*NCOM*")=1,"NCOM",IF(C7="","","MA"))) -> MA | F7: 30376 | J7: =IF(K7="","",IF(K7>29,"DISP.IDADE","")) -> DISP.IDADE | K7: =IF(F7="","",INT((TODAY()-F7)/365.25)) -> 42 | L7: Não | M7: Eliane | N7: - | O7: - | P7: - | Q7: - | R7: - | S7: -
A8: 2 | B8: 18904 | C8: LENI RODRIGUES DIAS | D8: F | E8: =IF(COUNTIF(I8,"*MC*")=1,"MC",IF(COUNTIF(I8,"*NCOM*")=1,"NCOM",IF(C8="","","MA"))) -> MA | F8: 23323 | J8: =IF(K8="","",IF(K8>29,"DISP.IDADE","")) -> DISP.IDADE | K8: =IF(F8="","",INT((TODAY()-F8)/365.25)) -> 61 | L8: Não | M8: Eliane | N8: - | O8: - | P8: - | Q8: - | R8: - | S8: -
A9: 3 | B9: 18828 | C9: MARIA DA SOLEDADE PENHA SILVA | D9: F | E9: =IF(ISNUMBER(FIND("TE",I9)),"TE",IF(ISNUMBER(FIND("MCC",I9)),"MCC",IF(ISNUMBER(FIND("MC",I9)),"MC","MA"))) -> MA | F9: 25983 | G9: 1258776170 | H9: 36934088-7 | J9: =IF(K9="","",IF(K9>29,"DISP.IDADE","")) -> DISP.IDADE | K9: =IF(F9="","",INT((TODAY()-F9)/365.25)) -> 54 | L9: Não | M9: Eliane | N9: - | O9: - | P9: - | Q9: - | R9: - | S9: - | V9: 65617894404
A10: 4 | E10: =IF(COUNTIF(I10,"*MC*")=1,"MC",IF(COUNTIF(I10,"*NCOM*")=1,"NCOM",IF(C10="","","MA"))) | J10: =IF(K10="","",IF(K10>29,"DISP.IDADE","")) | K10: =IF(F10="","",INT((TODAY()-F10)/365.25)) | L10: Não | M10: Eliane | N10: - | O10: - | P10: - | Q10: - | R10: - | S10: -
A11: 5 | E11: =IF(COUNTIF(I11,"*MC*")=1,"MC",IF(COUNTIF(I11,"*NCOM*")=1,"NCOM",IF(C11="","","MA"))) | J11: =IF(K11="","",IF(K11>29,"DISP.IDADE","")) | K11: =IF(F11="","",INT((TODAY()-F11)/365.25)) | L11: Não | M11: Eliane | N11: - | O11: - | P11: - | Q11: - | R11: - | S11: -
A12: 6 | E12: =IF(COUNTIF(I12,"*MC*")=1,"MC",IF(COUNTIF(I12,"*NCOM*")=1,"NCOM",IF(C12="","","MA"))) | J12: =IF(K12="","",IF(K12>29,"DISP.IDADE","")) | K12: =IF(F12="","",INT((TODAY()-F12)/365.25)) | L12: Não | M12: Eliane | N12: - | O12: - | P12: - | Q12: - | R12: - | S12: -
A13: 7 | E13: =IF(COUNTIF(I13,"*MC*")=1,"MC",IF(COUNTIF(I13,"*NCOM*")=1,"NCOM",IF(C13="","","MA"))) | J13: =IF(K13="","",IF(K13>29,"DISP.IDADE","")) | K13: =IF(F13="","",INT((TODAY()-F13)/365.25)) | L13: Não | M13: Eliane | N13: - | O13: - | P13: - | Q13: - | R13: - | S13: -
A14: 8 | E14: =IF(COUNTIF(I14,"*MC*")=1,"MC",IF(COUNTIF(I14,"*NCOM*")=1,"NCOM",IF(C14="","","MA"))) | J14: =IF(K14="","",IF(K14>29,"DISP.IDADE","")) | K14: =IF(F14="","",INT((TODAY()-F14)/365.25)) | L14: Não | M14: Eliane | N14: - | O14: - | P14: - | Q14: - | R14: - | S14: -
A15: 9 | E15: =IF(COUNTIF(I15,"*MC*")=1,"MC",IF(COUNTIF(I15,"*NCOM*")=1,"NCOM",IF(C15="","","MA"))) | J15: =IF(K15="","",IF(K15>29,"DISP.IDADE","")) | K15: =IF(F15="","",INT((TODAY()-F15)/365.25)) | L15: Não | M15: Eliane | N15: - | O15: - | P15: - | Q15: - | R15: - | S15: -
A16: 10 | E16: =IF(COUNTIF(I16,"*MC*")=1,"MC",IF(COUNTIF(I16,"*NCOM*")=1,"NCOM",IF(C16="","","MA"))) | J16: =IF(K16="","",IF(K16>29,"DISP.IDADE","")) | K16: =IF(F16="","",INT((TODAY()-F16)/365.25)) | L16: Não | M16: Eliane | N16: - | O16: - | P16: - | Q16: - | R16: - | S16: -
A17: 13 | E17: =IF(COUNTIF(I17,"*MC*")=1,"MC",IF(COUNTIF(I17,"*NCOM*")=1,"NCOM",IF(C17="","","MA"))) | J17: =IF(K17="","",IF(K17>29,"DISP.IDADE","")) | K17: =IF(F17="","",INT((TODAY()-F17)/365.25)) | L17: Não | M17: Eliane | N17: - | O17: - | P17: - | Q17: - | R17: - | S17: -
A18: 14 | E18: =IF(COUNTIF(I18,"*MC*")=1,"MC",IF(COUNTIF(I18,"*NCOM*")=1,"NCOM",IF(C18="","","MA"))) | J18: =IF(K18="","",IF(K18>29,"DISP.IDADE","")) | K18: =IF(F18="","",INT((TODAY()-F18)/365.25)) | L18: Não | M18: Eliane | N18: - | O18: - | P18: - | Q18: - | R18: - | S18: -
A19: 15 | E19: =IF(COUNTIF(I19,"*MC*")=1,"MC",IF(COUNTIF(I19,"*NCOM*")=1,"NCOM",IF(C19="","","MA"))) | J19: =IF(K19="","",IF(K19>29,"DISP.IDADE","")) | K19: =IF(F19="","",INT((TODAY()-F19)/365.25)) | L19: Não | M19: Eliane | N19: - | O19: - | P19: - | Q19: - | R19: - | S19: -
A20: 16 | E20: =IF(COUNTIF(I20,"*MC*")=1,"MC",IF(COUNTIF(I20,"*NCOM*")=1,"NCOM",IF(C20="","","MA"))) | J20: =IF(K20="","",IF(K20>29,"DISP.IDADE","")) | K20: =IF(F20="","",INT((TODAY()-F20)/365.25)) | L20: Não | M20: Eliane | N20: - | O20: - | P20: - | Q20: - | R20: - | S20: -
A21: 17 | E21: =IF(COUNTIF(I21,"*MC*")=1,"MC",IF(COUNTIF(I21,"*NCOM*")=1,"NCOM",IF(C21="","","MA"))) | J21: =IF(K21="","",IF(K21>29,"DISP.IDADE","")) | K21: =IF(F21="","",INT((TODAY()-F21)/365.25)) | L21: Não | M21: Eliane | N21: - | O21: - | P21: - | Q21: - | R21: - | S21: -
... A34: 30 | E34: =IF(COUNTIF(I34,"*MC*")=1,"MC",IF(COUNTIF(I34,"*NCOM*")=1,"NCOM",IF(C34="","","MA"))) | J34: =IF(K34="","",IF(K34>29,"DISP.IDADE","")) | K34: =IF(F34="","",INT((TODAY()-F34)/365.25)) | L34: Não | M34: Eliane | N34: - | O34: - | P34: - | Q34: - | R34: - | S34: -

Sheet 2ª
C1: Município da Estância Balneária de Praia Grande
C2: Estado de São Paulo
C3: E.M. José Padin Mouta
C4: EDUCAÇÃO DE JOVENS DE ADULTOS - EJA - 2º Sem/2025
A5: SÉRIE: 2ª SÉRIE E.F | D5: SALA: | G5: DATA IMPRESSÃO: | H5: =TODAY() -> 45931 | I5: NR. Classe: SED:
A6: Nº | B6: RM | C6: NOME DO ALUNO | D6: S | E6: COD | F6: NASC. | G6: RA | H6: RG | I6: OBS.: | J6: ED. FÍSICA | K6: IDADE | L6: INCLUSÃO | M6: PROFESSOR | N6: PLANO DE AÇÃO | O6: AEE | P6: DEFICIENCIA | Q6: OBS DEFICIENCIA: | R6: C. RODAS | S6: ADEQUAÇÕES | T6: TIPO TE | U6: LOCAL TE | V6: CPF
A7: 1 | B7: 13512 | C7: ADMILSON FRANCISCO DE SANTANA | D7: M | E7: =IF(ISNUMBER(FIND("TE",I7)),"TE",IF(ISNUMBER(FIND("MCC",I7)),"MCC",IF(ISNUMBER(FIND("MC",I7)),"MC","MA"))) -> MA | F7: 31434 | G7: 113917115-X | H7: 56170354-1 | J7: =IF(K7="","",IF(K7>29,"DISP.IDADE","")) -> DISP.IDADE | K7: =IF(F7="","",INT((TODAY()-F7)/365.25)) -> 39 | L7: Não | M7: Eliane | N7: - | O7: - | P7: - | Q7: - | R7: - | S7: - | V7: 36810921642
A8: 2 | B8: 18908 | C8: ELIANE IRENE DA SILVA SANTOS | D8: F | E8: =IF(COUNTIF(I8,"*MC*")=1,"MC",IF(COUNTIF(I8,"*NCOM*")=1,"NCOM",IF(C8="","","MA"))) -> MA | F8: 26448 | J8: =IF(K8="","",IF(K8>29,"DISP.IDADE","")) -> DISP.IDADE | K8: =IF(F8="","",INT((TODAY()-F8)/365.25)) -> 53 | L8: Não | M8: Eliane | N8: - | O8: - | P8: - | Q8: - | R8: - | S8: -
A9: 3 | B9: 18911 | C9: RITA DOS SANTOS CORREIA | D9: F | E9: =IF(COUNTIF(I9,"*MC*")=1,"MC",IF(COUNTIF(I9,"*NCOM*")=1,"NCOM",IF(C9="","","MA"))) -> MA | F9: 16697 | G9: 32468373-X | J9: =IF(K9="","",IF(K9>29,"DISP.IDADE","")) -> DISP.IDADE | K9: =IF(F9="","",INT((TODAY()-F9)/365.25)) -> 80 | L9: Não | M9: Eliane | N9: - | O9: - | P9: - | Q9: - | R9: - | S9: -
A10: 4 | B10: 18970 | C10: MARIA CLEUSA DOS SANTOS | D10: F | E10: =IF(COUNTIF(I10,"*MC*")=1,"MC",IF(COUNTIF(I10,"*NCOM*")=1,"NCOM",IF(C10="","","MA"))) -> MA | F10: 25393 | H10: 25427262-9 | J10: =IF(K10="","",IF(K10>29,"DISP.IDADE","")) -> DISP.IDADE | K10: =IF(F10="","",INT((TODAY()-F10)/365.25)) -> 56 | L10: Não | M10: Eliane | N10: - | O10: - | P10: - | Q10: - | R10: - | S10: - | V10: 19765619812
A11: 5 | E11: =IF(COUNTIF(I11,"*MC*")=1,"MC",IF(COUNTIF(I11,"*NCOM*")=1,"NCOM",IF(C11="","","MA"))) | J11: =IF(K11="","",IF(K11>29,"DISP.IDADE","")) | K11: =IF(F11="","",INT((TODAY()-F11)/365.25)) | L11: Não | M11: Eliane | N11: - | O11: - | P11: - | Q11: - | R11: - | S11: -
A12: 6 | E12: =IF(COUNTIF(I12,"*MC*")=1,"MC",IF(COUNTIF(I12,"*NCOM*")=1,"NCOM",IF(C12="","","MA"))) | J12: =IF(K12="","",IF(K12>29,"DISP.IDADE","")) | K12: =IF(F12="","",INT((TODAY()-F12)/365.25)) | L12: Não | M12: Eliane | N12: - | O12: - | P12: - | Q12: - | R12: - | S12: -
A13: 7 | E13: =IF(COUNTIF(I13,"*MC*")=1,"MC",IF(COUNTIF(I13,"*NCOM*")=1,"NCOM",IF(C13="","","MA"))) | J13: =IF(K13="","",IF(K13>29,"DISP.IDADE","")) | K13: =IF(F13="","",INT((TODAY()-F13)/365.25)) | L13: Não | M13: Eliane | N13: - | O13: - | P13: - | Q13: - | R13: - | S13: -
A14: 8 | E14: =IF(COUNTIF(I14,"*MC*")=1,"MC",IF(COUNTIF(I14,"*NCOM*")=1,"NCOM",IF(C14="","","MA"))) | J14: =IF(K14="","",IF(K14>29,"DISP.IDADE","")) | K14: =IF(F14="","",INT((TODAY()-F14)/365.25)) | L14: Não | M14: Eliane | N14: - | O14: - | P14: - | Q14: - | R14: - | S14: -
A15: 9 | E15: =IF(COUNTIF(I15,"*MC*")=1,"MC",IF(COUNTIF(I15,"*NCOM*")=1,"NCOM",IF(C15="","","MA"))) | J15: =IF(K15="","",IF(K15>29,"DISP.IDADE","")) | K15: =IF(F15="","",INT((TODAY()-F15)/365.25)) | L15: Não | M15: Eliane | N15: - | O15: - | P15: - | Q15: - | R15: - | S15: -
A16: 10 | E16: =IF(COUNTIF(I16,"*MC*")=1,"MC",IF(COUNTIF(I16,"*NCOM*")=1,"NCOM",IF(C16="","","MA"))) | J16: =IF(K16="","",IF(K16>29,"DISP.IDADE","")) | K16: =IF(F16="","",INT((TODAY()-F16)/365.25)) | L16: Não | M16: Eliane | N16: - | O16: - | P16: - | Q16: - | R16: - | S16: -
A17: 11 | E17: =IF(COUNTIF(I17,"*MC*")=1,"MC",IF(COUNTIF(I17,"*NCOM*")=1,"NCOM",IF(C17="","","MA"))) | J17: =IF(K17="","",IF(K17>29,"DISP.IDADE","")) | K17: =IF(F17="","",INT((TODAY()-F17)/365.25)) | L17: Não | M17: Eliane | N17: - | O17: - | P17: - | Q17: - | R17: - | S17: -
A18: 12 | E18: =IF(COUNTIF(I18,"*MC*")=1,"MC",IF(COUNTIF(I18,"*NCOM*")=1,"NCOM",IF(C18="","","MA"))) | J18: =IF(K18="","",IF(K18>29,"DISP.IDADE","")) | K18: =IF(F18="","",INT((TODAY()-F18)/365.25)) | L18: Não | M18: Eliane | N18: - | O18: - | P18: - | Q18: - | R18: - | S18: -
A19: 13 | E19: =IF(COUNTIF(I19,"*MC*")=1,"MC",IF(COUNTIF(I19,"*NCOM*")=1,"NCOM",IF(C19="","","MA"))) | J19: =IF(K19="","",IF(K19>29,"DISP.IDADE","")) | K19: =IF(F19="","",INT((TODAY()-F19)/365.25)) | L19: Não | M19: Eliane | N19: - | O19: - | P19: - | Q19: - | R19: - | S19: -
A20: 14 | E20: =IF(COUNTIF(I20,"*MC*")=1,"MC",IF(COUNTIF(I20,"*NCOM*")=1,"NCOM",IF(C20="","","MA"))) | J20: =IF(K20="","",IF(K20>29,"DISP.IDADE","")) | K20: =IF(F20="","",INT((TODAY()-F20)/365.25)) | L20: Não | M20: Eliane | N20: - | O20: - | P20: - | Q20: - | R20: - | S20: -
A21: 15 | E21: =IF(COUNTIF(I21,"*MC*")=1,"MC",IF(COUNTIF(I21,"*NCOM*")=1,"NCOM",IF(C21="","","MA"))) | J21: =IF(K21="","",IF(K21>29,"DISP.IDADE","")) | K21: =IF(F21="","",INT((TODAY()-F21)/365.25)) | L21: Não | M21: Eliane | N21: - | O21: - | P21: - | Q21: - | R21: - | S21: -
A22: 16 | E22: =IF(COUNTIF(I22,"*MC*")=1,"MC",IF(COUNTIF(I22,"*NCOM*")=1,"NCOM",IF(C22="","","MA"))) | J22: =IF(K22="","",IF(K22>29,"DISP.IDADE","")) | K22: =IF(F22="","",INT((TODAY()-F22)/365.25)) | L22: Não | M22: Eliane | N22: - | O22: - | P22: - | Q22: - | R22: - | S22: -
... A32: 26 | E32: =IF(COUNTIF(I32,"*MC*")=1,"MC",IF(COUNTIF(I32,"*NCOM*")=1,"NCOM",IF(C32="","","MA"))) | J32: =IF(K32="","",IF(K32>29,"DISP.IDADE","")) | K32: =IF(F32="","",INT((TODAY()-F32)/365.25)) | L32: Não | M32: Eliane | N32: - | O32: - | P32: - | Q32: - | R32: - | S32: -

Sheet 3ª
C1: Município da Estância Balneária de Praia Grande
C2: Estado de São Paulo
C3: E.M. José Padin Mouta
C4: EDUCAÇÃO DE JOVENS DE ADULTOS - EJA - 2º Sem/2025
A5: SÉRIE: 3ª SÉRIE E.F | D5: SALA: | G5: DATA IMPRESSÃO: | H5: =TODAY() -> 45931 | I5: NR. Classe: SED:
A6: Nº | B6: RM | C6: NOME DO ALUNO | D6: S | E6: COD | F6: NASC. | G6: RA | H6: RG | I6: OBS.: | J6: ED. FÍSICA | K6: IDADE | L6: INCLUSÃO | M6: PROFESSOR | N6: PLANO DE AÇÃO | O6: AEE | P6: DEFICIENCIA | Q6: OBS DEFICIENCIA: | R6: C. RODAS | S6: ADEQUAÇÕES | T6: TIPO TE | U6: LOCAL TE | V6: CPF
A7: 1 | B7: 18767 | C7: CLAUDEMIR JOSE DE AMORIM | D7: M | E7: =IF(ISNUMBER(FIND("TE",I7)),"TE",IF(ISNUMBER(FIND("MCC",I7)),"MCC",IF(ISNUMBER(FIND("MC",I7)),"MC","MA"))) -> MA | F7: 24673 | H7: 69889673-7 | J7: =IF(K7="","",IF(K7>29,"DISP.IDADE","")) -> DISP.IDADE | K7: =IF(F7="","",INT((TODAY()-F7)/365.25)) -> 58 | L7: Não | M7: Eliane | N7: - | O7: - | P7: - | Q7: - | R7: - | S7: - | V7: 3717075799
A8: 2 | B8: 18837 | C8: DIEGO RYAN SANTOS DE ALCANTARA | D8: M | E8: =IF(ISNUMBER(FIND("TE",I8)),"TE",IF(ISNUMBER(FIND("MCC",I8)),"MCC",IF(ISNUMBER(FIND("MC",I8)),"MC","MA"))) -> MA | F8: 40045 | G8: 111223789-6 | J8: =IF(K8="","",IF(K8>29,"DISP.IDADE","")) | K8: =IF(F8="","",INT((TODAY()-F8)/365.25)) -> 16 | L8: Não | M8: Eliane | N8: - | O8: - | P8: - | Q8: - | R8: - | S8: - | V8: 38253371896
A9: 3 | B9: 17989 | C9: ELISA DA COSTA BARRETO | D9: F | E9: =IF(ISNUMBER(FIND("TE",I9)),"TE",IF(ISNUMBER(FIND("MCC",I9)),"MCC",IF(ISNUMBER(FIND("MC",I9)),"MC","MA"))) -> MC | F9: 24447 | G9: 124351785-2 | H9: 52171529-5 | I9: MC - 20/08 | J9: =IF(K9="","",IF(K9>29,"DISP.IDADE","")) -> DISP.IDADE | K9: =IF(F9="","",INT((TODAY()-F9)/365.25)) -> 58 | L9: Não | M9: Eliane | N9: - | O9: - | P9: - | Q9: - | R9: - | S9: - | T9: Sem Informação | U9: MC por Solicitação do Responsavel | V9: 48456511353
A10: 4 | B10: 18839 | C10: JOSE MIGUEL DA SILVA FILHO | D10: M | E10: =IF(ISNUMBER(FIND("TE",I10)),"TE",IF(ISNUMBER(FIND("MCC",I10)),"MCC",IF(ISNUMBER(FIND("MC",I10)),"MC","MA"))) -> MA | F10: 26939 | H10: 26885705 | J10: =IF(K10="","",IF(K10>29,"DISP.IDADE","")) -> DISP.IDADE | K10: =IF(F10="","",INT((TODAY()-F10)/365.25)) -> 51 | L10: Não | M10: Eliane | N10: - | O10: - | P10: - | Q10: - | R10: - | S10: - | V10: 16960997810
A11: 5 | B11: 18357 | C11: JOSETE FERREIRA DAMIAO DA SILVA | D11: F | E11: =IF(ISNUMBER(FIND("TE",I11)),"TE",IF(ISNUMBER(FIND("MCC",I11)),"MCC",IF(ISNUMBER(FIND("MC",I11)),"MC","MA"))) -> MC | F11: 23056 | H11: 67130928-6 | I11: MC - 05/08 | J11: =IF(K11="","",IF(K11>29,"DISP.IDADE","")) -> DISP.IDADE | K11: =IF(F11="","",INT((TODAY()-F11)/365.25)) -> 62 | L11: Não | M11: Eliane | N11: - | O11: - | P11: - | Q11: - | R11: - | S11: - | T11: Sem Informação | U11: MC por Solicitação do Responsavel | V11: 55503535472
A12: 6 | B12: 18747 | C12: MARIA LUCIA LEITE DE OLIVEIRA | D12: F | E12: =IF(ISNUMBER(FIND("TE",I12)),"TE",IF(ISNUMBER(FIND("MCC",I12)),"MCC",IF(ISNUMBER(FIND("MC",I12)),"MC","MA"))) -> MA | F12: 21869 | H12: 131542312 | J12: =IF(K12="","",IF(K12>29,"DISP.IDADE","")) -> DISP.IDADE | K12: =IF(F12="","",INT((TODAY()-F12)/365.25)) -> 65 | L12: Não | M12: Eliane | N12: - | O12: - | P12: - | Q12: - | R12: - | S12: - | V12: 4469768812
A13: 7 | B13: 18906 | C13: MYKAELLY CRISTINA CARVALHO CAMPOS | D13: F | E13: =IF(COUNTIF(I13,"*MC*")=1,"MC",IF(COUNTIF(I13,"*NCOM*")=1,"NCOM",IF(C13="","","MA"))) -> MA | F13: 40161 | G13: 113758780-5 | J13: =IF(K13="","",IF(K13>29,"DISP.IDADE","")) | K13: =IF(F13="","",INT((TODAY()-F13)/365.25)) -> 15 | L13: Não | M13: Eliane | N13: - | O13: - | P13: - | Q13: - | R13: - | S13: -
A14: 8 | E14: =IF(COUNTIF(I14,"*MC*")=1,"MC",IF(COUNTIF(I14,"*NCOM*")=1,"NCOM",IF(C14="","","MA"))) | J14: =IF(K14="","",IF(K14>29,"DISP.IDADE","")) | K14: =IF(F14="","",INT((TODAY()-F14)/365.25)) | L14: Não | M14: Eliane | N14: - | O14: - | P14: - | Q14: - | R14: - | S14: -
A15: 9 | E15: =IF(COUNTIF(I15,"*MC*")=1,"MC",IF(COUNTIF(I15,"*NCOM*")=1,"NCOM",IF(C15="","","MA"))) | J15: =IF(K15="","",IF(K15>29,"DISP.IDADE","")) | K15: =IF(F15="","",INT((TODAY()-F15)/365.25)) | L15: Não | M15: Eliane | N15: - | O15: - | P15: - | Q15: - | R15: - | S15: -
A16: 10 | E16: =IF(COUNTIF(I16,"*MC*")=1,"MC",IF(COUNTIF(I16,"*NCOM*")=1,"NCOM",IF(C16="","","MA"))) | J16: =IF(K16="","",IF(K16>29,"DISP.IDADE","")) | K16: =IF(F16="","",INT((TODAY()-F16)/365.25)) | L16: Não | M16: Eliane | N16: - | O16: - | P16: - | Q16: - | R16: - | S16: -
A17: 11 | E17: =IF(COUNTIF(I17,"*MC*")=1,"MC",IF(COUNTIF(I17,"*NCOM*")=1,"NCOM",IF(C17="","","MA"))) | J17: =IF(K17="","",IF(K17>29,"DISP.IDADE","")) | K17: =IF(F17="","",INT((TODAY()-F17)/365.25)) | L17: Não | M17: Eliane | N17: - | O17: - | P17: - | Q17: - | R17: - | S17: -
A18: 12 | E18: =IF(COUNTIF(I18,"*MC*")=1,"MC",IF(COUNTIF(I18,"*NCOM*")=1,"NCOM",IF(C18="","","MA"))) | J18: =IF(K18="","",IF(K18>29,"DISP.IDADE","")) | K18: =IF(F18="","",INT((TODAY()-F18)/365.25)) | L18: Não | M18: Eliane | N18: - | O18: - | P18: - | Q18: - | R18: - | S18: -
A19: 13 | E19: =IF(COUNTIF(I19,"*MC*")=1,"MC",IF(COUNTIF(I19,"*NCOM*")=1,"NCOM",IF(C19="","","MA"))) | J19: =IF(K19="","",IF(K19>29,"DISP.IDADE","")) | K19: =IF(F19="","",INT((TODAY()-F19)/365.25)) | L19: Não | M19: Eliane | N19: - | O19: - | P19: - | Q19: - | R19: - | S19: -
A20: 14 | E20: =IF(COUNTIF(I20,"*MC*")=1,"MC",IF(COUNTIF(I20,"*NCOM*")=1,"NCOM",IF(C20="","","MA"))) | J20: =IF(K20="","",IF(K20>29,"DISP.IDADE","")) | K20: =IF(F20="","",INT((TODAY()-F20)/365.25)) | L20: Não | M20: Eliane | N20: - | O20: - | P20: - | Q20: - | R20: - | S20: -
A21: 15 | E21: =IF(COUNTIF(I21,"*MC*")=1,"MC",IF(COUNTIF(I21,"*NCOM*")=1,"NCOM",IF(C21="","","MA"))) | J21: =IF(K21="","",IF(K21>29,"DISP.IDADE","")) | K21: =IF(F21="","",INT((TODAY()-F21)/365.25)) | L21: Não | M21: Eliane | N21: - | O21: - | P21: - | Q21: - | R21: - | S21: -
A22: 16 | E22: =IF(COUNTIF(I22,"*MC*")=1,"MC",IF(COUNTIF(I22,"*NCOM*")=1,"NCOM",IF(C22="","","MA"))) | J22: =IF(K22="","",IF(K22>29,"DISP.IDADE","")) | K22: =IF(F22="","",INT((TODAY()-F22)/365.25)) | L22: Não | M22: Eliane | N22: - | O22: - | P22: - | Q22: - | R22: - | S22: -
A23: 17 | E23: =IF(COUNTIF(I23,"*MC*")=1,"MC",IF(COUNTIF(I23,"*NCOM*")=1,"NCOM",IF(C23="","","MA"))) | J23: =IF(K23="","",IF(K23>29,"DISP.IDADE","")) | K23: =IF(F23="","",INT((TODAY()-F23)/365.25)) | L23: Não | M23: Eliane | N23: - | O23: - | P23: - | Q23: - | R23: - | S23: -
A24: 18 | E24: =IF(COUNTIF(I24,"*MC*")=1,"MC",IF(COUNTIF(I24,"*NCOM*")=1,"NCOM",IF(C24="","","MA"))) | J24: =IF(K24="","",IF(K24>29,"DISP.IDADE","")) | K24: =IF(F24="","",INT((TODAY()-F24)/365.25)) | L24: Não | M24: Eliane | N24: - | O24: - | P24: - | Q24: - | R24: - | S24: -
A25: 19 | E25: =IF(COUNTIF(I25,"*MC*")=1,"MC",IF(COUNTIF(I25,"*NCOM*")=1,"NCOM",IF(C25="","","MA"))) | J25: =IF(K25="","",IF(K25>29,"DISP.IDADE","")) | K25: =IF(F25="","",INT((TODAY()-F25)/365.25)) | L25: Não | M25: Eliane | N25: - | O25: - | P25: - | Q25: - | R25: - | S25: -
... A36: 30 | E36: =IF(COUNTIF(I36,"*MC*")=1,"MC",IF(COUNTIF(I36,"*NCOM*")=1,"NCOM",IF(C36="","","MA"))) | J36: =IF(K36="","",IF(K36>29,"DISP.IDADE","")) | K36: =IF(F36="","",INT((TODAY()-F36)/365.25)) | L36: Não | M36: Eliane | N36: - | O36: - | P36: - | Q36: - | R36: - | S36: -

Sheet 4ª
C1: Município da Estância Balneária de Praia Grande
C2: Estado de São Paulo
C3: E.M. José Padin Mouta
C4: EDUCAÇÃO DE JOVENS DE ADULTOS - EJA - 2º Sem/2025
A5: SÉRIE: 4ª SÉRIE E.F | D5: SALA: | G5: DATA IMPRESSÃO: | H5: =TODAY() -> 45931 | I5: NR. Classe: SED:
A6: Nº | B6: RM | C6: NOME DO ALUNO | D6: S | E6: COD | F6: NASC. | G6: RA | H6: RG | I6: OBS.: | J6: ED. FÍSICA | K6: IDADE | L6: INCLUSÃO | M6: PROFESSOR | N6: PLANO DE AÇÃO | O6: AEE | P6: DEFICIENCIA | Q6: OBS DEFICIENCIA: | R6: C. RODAS | S6: ADEQUAÇÕES | T6: TIPO TE | U6: LOCAL TE | V6: CPF
A7: 1 | B7: 18844 | C7: DEBORA CRISTINA GOIS | D7: F | E7: =IF(ISNUMBER(FIND("TE",I7)),"TE",IF(ISNUMBER(FIND("MCC",I7)),"MCC",IF(ISNUMBER(FIND("MC",I7)),"MC","MA"))) -> MA | F7: 27676 | H7: 24.175.609-1 | J7: =IF(K7="","",IF(K7>29,"DISP.IDADE","")) -> DISP.IDADE | K7: =IF(F7="","",INT((TODAY()-F7)/365.25)) -> 49 | L7: Não | M7: Eliane | N7: - | O7: - | P7: - | Q7: - | R7: - | S7: - | V7: 14981407858
A8: 2 | B8: 18903 | C8: EDUARDO PEREIRA DA SILVA | D8: M | E8: =IF(COUNTIF(I8,"*MC*")=1,"MC",IF(COUNTIF(I8,"*NCOM*")=1,"NCOM",IF(C8="","","MA"))) -> MA | F8: 29004 | J8: =IF(K8="","",IF(K8>29,"DISP.IDADE","")) -> DISP.IDADE | K8: =IF(F8="","",INT((TODAY()-F8)/365.25)) -> 46 | L8: Não | M8: Eliane | N8: - | O8: - | P8: - | Q8: - | R8: - | S8: -
A9: 3 | B9: 15909 | C9: ELISANGELA VIANA DOS SANTOS | D9: F | E9: =IF(ISNUMBER(FIND("TE",I9)),"TE",IF(ISNUMBER(FIND("MCC",I9)),"MCC",IF(ISNUMBER(FIND("MC",I9)),"MC","MA"))) -> MC | F9: 30299 | G9: 105910197-X | H9: 36042775-3 | I9: MC - 30/09 | J9: =IF(K9="","",IF(K9>29,"DISP.IDADE","")) -> DISP.IDADE | K9: =IF(F9="","",INT((TODAY()-F9)/365.25)) -> 42 | L9: Não | M9: Eliane | N9: - | O9: - | P9: - | Q9: - | R9: - | S9: - | V9: 595488651
A10: 4 | B10: 18910 | C10: JOÃO VITHOR ANDRADE BARBOSA | D10: M | E10: =IF(COUNTIF(I10,"*MC*")=1,"MC",IF(COUNTIF(I10,"*NCOM*")=1,"NCOM",IF(C10="","","MA"))) -> MA | F10: 40311 | G10: 1111887470 | J10: =IF(K10="","",IF(K10>29,"DISP.IDADE","")) | K10: =IF(F10="","",INT((TODAY()-F10)/365.25)) -> 15 | L10: Não | M10: Eliane | N10: - | O10: - | P10: - | Q10: - | R10: - | S10: -
A11: 5 | B11: 15109 | C11: JOEL SILVA SANTOS | D11: M | E11: =IF(ISNUMBER(FIND("TE",I11)),"TE",IF(ISNUMBER(FIND("MCC",I11)),"MCC",IF(ISNUMBER(FIND("MC",I11)),"MC","MA"))) -> MC | F11: 20529 | G11: 116443134-1 | H11: 52316564-X | I11: MC - 14/07 | J11: =IF(K11="","",IF(K11>29,"DISP.IDADE","")) -> DISP.IDADE | K11: =IF(F11="","",INT((TODAY()-F11)/365.25)) -> 69 | L11: Não | M11: Eliane | N11: - | O11: - | P11: - | Q11: - | R11: - | S11: - | T11: Sem Informação | U11: Solicitação do Aluno/Responsável | V11: 52136564X
A12: 6 | B12: 16431 | C12: JOSE EDUARDO DA SILVA | D12: M | E12: =IF(ISNUMBER(FIND("TE",I12)),"TE",IF(ISNUMBER(FIND("MCC",I12)),"MCC",IF(ISNUMBER(FIND("MC",I12)),"MC","MA"))) -> MA | F12: 25052 | H12: 35247676-X | J12: =IF(K12="","",IF(K12>29,"DISP.IDADE","")) -> DISP.IDADE | K12: =IF(F12="","",INT((TODAY()-F12)/365.25)) -> 57 | L12: Não | M12: Eliane | N12: - | O12: - | P12: - | Q12: - | R12: - | S12: - | V12: 27383355865
A13: 7 | B13: 16682 | C13: MARGARIDA BERNARDINA DOS SANTOS | D13: F | E13: =IF(ISNUMBER(FIND("TE",I13)),"TE",IF(ISNUMBER(FIND("MCC",I13)),"MCC",IF(ISNUMBER(FIND("MC",I13)),"MC","MA"))) -> MA | F13: 19436 | G13: 122047495-2 | H13: 19716916 | J13: =IF(K13="","",IF(K13>29,"DISP.IDADE","")) -> DISP.IDADE | K13: =IF(F13="","",INT((TODAY()-F13)/365.25)) -> 72 | L13: Não | M13: Eliane | N13: - | O13: - | P13: - | Q13: - | R13: - | S13: - | V13: 21589931890
A14: 8 | B14: 18899 | C14: NADIR ESPINDOLA DA SILVA | D14: F | E14: =IF(COUNTIF(I14,"*MC*")=1,"MC",IF(COUNTIF(I14,"*NCOM*")=1,"NCOM",IF(C14="","","MA"))) -> MA | F14: 17179 | H14: 8400889-1 | J14: =IF(K14="","",IF(K14>29,"DISP.IDADE","")) -> DISP.IDADE | K14: =IF(F14="","",INT((TODAY()-F14)/365.25)) -> 78 | L14: Não | M14: Eliane | N14: - | O14: - | P14: - | Q14: - | R14: - | S14: - | V14: 03181205850
A15: 9 | B15: 18539 | C15: REGINA BARBOSA DE SOUZA BATISTA | D15: F | E15: =IF(ISNUMBER(FIND("TE",I15)),"TE",IF(ISNUMBER(FIND("MCC",I15)),"MCC",IF(ISNUMBER(FIND("MC",I15)),"MC","MA"))) -> MA | F15: 17784 | H15: 5891392-0 | J15: =IF(K15="","",IF(K15>29,"DISP.IDADE","")) -> DISP.IDADE | K15: =IF(F15="","",INT((TODAY()-F15)/365.25)) -> 77 | L15: Não | M15: Eliane | N15: - | O15: - | P15: - | Q15: - | R15: - | S15: - | V15: 8950632802
A16: 10 | B16: 18923 | C16: ROSANGELA BORGES DE ABREU | D16: F | E16: =IF(COUNTIF(I16,"*MC*")=1,"MC",IF(COUNTIF(I16,"*NCOM*")=1,"NCOM",IF(C16="","","MA"))) -> MC | F16: 29923 | H16: 372470282 | I16: MC - 30/09 | J16: =IF(K16="","",IF(K16>29,"DISP.IDADE","")) -> DISP.IDADE | K16: =IF(F16="","",INT((TODAY()-F16)/365.25)) -> 43 | L16: Não | M16: Eliane | N16: - | O16: - | P16: - | Q16: - | R16: - | S16: -
A17: 11 | B17: 10330 | C17: SAMARA VITORIA FERREIRA SANTANA | D17: F | E17: =IF(COUNTIF(I17,"*MC*")=1,"MC",IF(COUNTIF(I17,"*NCOM*")=1,"NCOM",IF(C17="","","MA"))) -> MA | F17: 37324 | H17: 69004191-3 | J17: =IF(K17="","",IF(K17>29,"DISP.IDADE","")) | K17: =IF(F17="","",INT((TODAY()-F17)/365.25)) -> 23 | L17: Não | M17: Eliane | N17: - | O17: - | P17: - | Q17: - | R17: - | S17: -
A18: 12 | B18: 18745 | C18: VERA LUCIA BATISTA | D18: F | E18: =IF(ISNUMBER(FIND("TE",I18)),"TE",IF(ISNUMBER(FIND("MCC",I18)),"MCC",IF(ISNUMBER(FIND("MC",I18)),"MC","MA"))) -> MA | F18: 20637 | H18: 12637069-2 | J18: =IF(K18="","",IF(K18>29,"DISP.IDADE","")) -> DISP.IDADE | K18: =IF(F18="","",INT((TODAY()-F18)/365.25)) -> 69 | L18: Não | M18: Eliane | N18: - | O18: - | P18: - | Q18: - | R18: - | S18: -
A19: 13 | B19: 18947 | C19: MARIA VALDENICE MAJOR SOUZA | D19: F | E19: =IF(COUNTIF(I19,"*MC*")=1,"MC",IF(COUNTIF(I19,"*NCOM*")=1,"NCOM",IF(C19="","","MA"))) -> MA | F19: 24739 | H19: 28346876-2 | J19: =IF(K19="","",IF(K19>29,"DISP.IDADE","")) -> DISP.IDADE | K19: =IF(F19="","",INT((TODAY()-F19)/365.25)) -> 58 | L19: Não | M19: Eliane | N19: - | O19: - | P19: - | Q19: - | R19: - | S19: - | V19: 42970539500
A20: 14 | E20: =IF(COUNTIF(I20,"*MC*")=1,"MC",IF(COUNTIF(I20,"*NCOM*")=1,"NCOM",IF(C20="","","MA"))) | J20: =IF(K20="","",IF(K20>29,"DISP.IDADE","")) | K20: =IF(F20="","",INT((TODAY()-F20)/365.25)) | L20: Não | M20: Eliane | N20: - | O20: - | P20: - | Q20: - | R20: - | S20: -
A21: 15 | E21: =IF(COUNTIF(I21,"*MC*")=1,"MC",IF(COUNTIF(I21,"*NCOM*")=1,"NCOM",IF(C21="","","MA"))) | J21: =IF(K21="","",IF(K21>29,"DISP.IDADE","")) | K21: =IF(F21="","",INT((TODAY()-F21)/365.25)) | L21: Não | M21: Eliane | N21: - | O21: - | P21: - | Q21: - | R21: - | S21: -
